{"error": ["Traceback (most recent call last):", "  File \"error.py\", line 29, in <module>", "    test()", "  File \"<string>\", line 7, in test", "  File \"/anaconda/envs/torch13/lib/python3.8/site-packages/sklearn/metrics/_ranking.py\", line 572, in roc_auc_score", "    return _average_binary_score(", "  File \"/anaconda/envs/torch13/lib/python3.8/site-packages/sklearn/metrics/_base.py\", line 75, in _average_binary_score", "    return binary_metric(y_true, y_score, sample_weight=sample_weight)", "  File \"/anaconda/envs/torch13/lib/python3.8/site-packages/sklearn/metrics/_ranking.py\", line 339, in _binary_roc_auc_score", "    raise ValueError(", "ValueError: Only one class present in y_true. ROC AUC score is not defined in that case.", ""], "code": ["import numpy as np", "from sklearn.metrics import roc_auc_score", "", "def test():", "    y_true = np.array([0, 0, 0, 0])", "    y_scores = np.array([1, 0, 0, 0])", "    roc_auc_score(y_true, y_scores)"], "context": ["", "You could use try-except to prevent the error:", "```", "import numpy as np", "from sklearn.metrics import roc_auc_score", "y_true = np.array([0, 0, 0, 0])", "y_scores = np.array([1, 0, 0, 0])", "try:", "    roc_auc_score(y_true, y_scores)", "except ValueError:", "    pass", "```", "", "Now you can also set the `roc_auc_score` to be zero if there is only one class present. However, I wouldn't do this. I guess your test data is highly unbalanced. I would suggest to use stratified K-fold instead so that you at least have both classes present. ", ""], "ideal": ["import numpy as np", "from sklearn.metrics import roc_auc_score", "", "def test():", "    y_true = np.array([0, 0, 0, 0])", "    y_scores = np.array([1, 0, 0, 0])", "    try:", "        roc_auc_score(y_true, y_scores)", "    except ValueError:", "        pass"], "context_url": "https://stackoverflow.com/questions/45139163/roc-auc-score-only-one-class-present-in-y-true", "context_author_url": ["https://stackoverflow.com/users/3968028/dat-tran"]}
{"error": ["Traceback (most recent call last):", "  File \"error.py\", line 24, in <module>", "    test()", "  File \"<string>\", line 4, in test", "  File \"/anaconda/envs/torch13/lib/python3.8/site-packages/nltk/tokenize/__init__.py\", line 106, in sent_tokenize", "    tokenizer = load(f\"tokenizers/punkt/{language}.pickle\")", "  File \"/anaconda/envs/torch13/lib/python3.8/site-packages/nltk/data.py\", line 750, in load", "    opened_resource = _open(resource_url)", "  File \"/anaconda/envs/torch13/lib/python3.8/site-packages/nltk/data.py\", line 876, in _open", "    return find(path_, path + [\"\"]).open()", "  File \"/anaconda/envs/torch13/lib/python3.8/site-packages/nltk/data.py\", line 583, in find", "    raise LookupError(resource_not_found)", "LookupError: ", "**********************************************************************", "  Resource \u001b[93mpunkt\u001b[0m not found.", "  Please use the NLTK Downloader to obtain the resource:", "", "  \u001b[31m>>> import nltk", "  >>> nltk.download('punkt')", "  \u001b[0m", "  For more information see: https://www.nltk.org/data.html", "", "  Attempted to load \u001b[93mtokenizers/punkt/PY3/english.pickle\u001b[0m", "", "  Searched in:", "    - '/home/xxxx/nltk_data'", "    - '/anaconda/envs/torch13/nltk_data'", "    - '/anaconda/envs/torch13/share/nltk_data'", "    - '/anaconda/envs/torch13/lib/nltk_data'", "    - '/usr/share/nltk_data'", "    - '/usr/local/share/nltk_data'", "    - '/usr/lib/nltk_data'", "    - '/usr/local/lib/nltk_data'", "    - ''", "**********************************************************************", "", ""], "code": ["from nltk.tokenize import sent_tokenize", "", "def test():", "    rslt = sent_tokenize(\"This is a simple test. Is it right?\")", "    return rslt"], "context": ["", "Use ", "```", ">>> nltk.download()", "```", "", "to install the missing module (the Perceptron Tagger).", "(check also the answers to Failed loading english.pickle with nltk.data.load)", ""], "ideal": ["from nltk.tokenize import sent_tokenize", "import nltk", "nltk.download('punkt')", "", "def test():", "    rslt = sent_tokenize(\"This is a simple test. Is it right?\")", "    return rslt"], "context_url": "https://stackoverflow.com/questions/35861482/nltk-lookup-error", "context_author_url": ["https://stackoverflow.com/users/-1/community", "https://stackoverflow.com/users/2314737/user2314737"]}
{"error": ["Traceback (most recent call last):", "  File \"error.py\", line 22, in <module>", "    exec(\"\\n\".join(data[\"code\"]))", "  File \"<string>\", line 14, in <module>", "  File \"/anaconda/envs/torch13/lib/python3.8/site-packages/torch/utils/data/dataloader.py\", line 681, in __next__", "    data = self._next_data()", "  File \"/anaconda/envs/torch13/lib/python3.8/site-packages/torch/utils/data/dataloader.py\", line 720, in _next_data", "    index = self._next_index()  # may raise StopIteration", "  File \"/anaconda/envs/torch13/lib/python3.8/site-packages/torch/utils/data/dataloader.py\", line 671, in _next_index", "    return next(self._sampler_iter)  # may raise StopIteration", "  File \"/anaconda/envs/torch13/lib/python3.8/site-packages/torch/utils/data/sampler.py\", line 247, in __iter__", "    for idx in self.sampler:", "  File \"/anaconda/envs/torch13/lib/python3.8/site-packages/torch/utils/data/sampler.py\", line 76, in __iter__", "    return iter(range(len(self.data_source)))", "TypeError: object of type 'MyDataset' has no len()", ""], "code": ["import torch", "from torch.utils.data import Dataset, DataLoader", "", "class MyDataset(Dataset):", "    def __init__(self, values):", "        self.values = values", "    ", "    def __getitem__(self, idx):", "        return self.values[idx]", "", "ds = MyDataset(torch.randn(100))", "dl=DataLoader(ds, batch_size=8, num_workers=0)", "", "for idx,data in enumerate(dl):", "    print(data.shape)"], "context": ["", "The error is actually pretty specific on the error, the error that was raised is NotImplementedError. You are supposed to implement the `__len__` function in your custom dataset.", "In your case that would be as simple as (assuming `self.data_image` contains all your dataset instances) adding this function to the `data_test` class:", "```", "    def __len__(self):", "        return len(self.data_image)", "```", "", ""], "ideal": ["import torch", "from torch.utils.data import Dataset, DataLoader", "", "class MyDataset(Dataset):", "    def __init__(self, values):", "        self.values = values", "    ", "    def __getitem__(self, idx):", "        return self.values[idx]", "    ", "    def __len__(self):", "        return len(self.values)", "", "ds = MyDataset(torch.randn(100))", "dl=DataLoader(ds, batch_size=8, num_workers=0)", "", "for idx,data in enumerate(dl):", "    print(data.shape)"], "context_url": "https://stackoverflow.com/questions/69006831/something-wrong-when-i-use-the-dataloader", "context_author_url": ["https://stackoverflow.com/users/6331369/ivan"]}
{"error": ["Traceback (most recent call last):", "  File \"error.py\", line 22, in <module>", "    test()", "  File \"<string>\", line 6, in test", "TypeError: a bytes-like object is required, not 'str'", ""], "code": ["import json", "", "def test():", "    data = \"hello world!\"", "    f = open('data.json', 'wb')", "    f.write(json.dumps(data))"], "context": ["", "`data` is a Python dictionary. It needs to be encoded as JSON before writing.", "Use this for maximum compatibility (Python 2 and 3):", "```", "import json", "with open('data.json', 'w') as f:", "    json.dump(data, f)", "```", "", "On a modern system (i.e. Python 3 and UTF-8 support), you can write a nicer file using:", "```", "import json", "with open('data.json', 'w', encoding='utf-8') as f:", "    json.dump(data, f, ensure_ascii=False, indent=4)", "```", "", "See json documentation.", ""], "ideal": ["import json", "", "def test():", "    data = \"hello world!\"", "    f = open('data.json', 'w')", "    f.write(json.dumps(data))", "    f.close()"], "context_url": "https://stackoverflow.com/questions/12309269/how-do-i-write-json-data-to-a-file", "context_author_url": ["https://stackoverflow.com/users/365102/mateen-ulhaq", "https://stackoverflow.com/users/35070/phihag"]}
{"error": ["Traceback (most recent call last):", "  File \"error.py\", line 25, in <module>", "    test()", "  File \"<string>\", line 4, in test", "AttributeError: 'generator' object has no attribute 'sort'", ""], "code": ["from pathlib import Path", "", "def test():", "    return Path(\".\").iterdir().sort()"], "context": ["", "As the error indicates, generators do not have a `sort` method. You can instead exhaust a generator via built-in sorted, which accepts an iterable as an input. Here's a trivial example:", "```", "def randoms(n):", "    import random", "    for _ in range(n):", "        yield random.randint(0, 10)", "", "res = sorted(randoms(10))  # [1, 2, 4, 5, 6, 6, 6, 7, 8, 10]", "res = randoms(10).sort()   # AttributeError: 'generator' object has no attribute 'sort'", "```", "", ""], "ideal": ["from pathlib import Path", "", "def test():", "    return sorted(Path(\".\").iterdir())"], "context_url": "https://stackoverflow.com/questions/52775382/attributeerror-generator-object-has-no-attribute-sort", "context_author_url": ["https://stackoverflow.com/users/9209546/jpp"]}
{"error": ["Traceback (most recent call last):", "  File \"error.py\", line 24, in <module>", "    test()", "  File \"<string>\", line 14, in test", "  File \"/anaconda/envs/torch13/lib/python3.8/site-packages/torch/nn/modules/module.py\", line 1130, in _call_impl", "    return forward_call(*input, **kwargs)", "  File \"/anaconda/envs/torch13/lib/python3.8/site-packages/torch/nn/modules/container.py\", line 139, in forward", "    input = module(input)", "  File \"/anaconda/envs/torch13/lib/python3.8/site-packages/torch/nn/modules/module.py\", line 1130, in _call_impl", "    return forward_call(*input, **kwargs)", "  File \"/anaconda/envs/torch13/lib/python3.8/site-packages/torch/nn/modules/linear.py\", line 114, in forward", "    return F.linear(input, self.weight, self.bias)", "RuntimeError: expected scalar type Float but found Double", ""], "code": ["import torch", "from torch import nn", "import numpy as np", "", "def test():", "    x = np.zeros((3,10))", "    x = torch.from_numpy(x)", "    model = nn.Sequential(", "        nn.Linear(10, 16),", "        nn.ReLU(),", "        nn.Linear(16, 3),", "        nn.LogSoftmax(dim = 1)", "    )", "    y = model(x)"], "context": ["", "Reference is from this github issue.", "When the error is `RuntimeError: Expected object of scalar type Float but got scalar type Double for argument #4 'mat1'`, you would need to use the `.float()` function since it says `Expected object of scalar type Float`.", "Therefore, the solution is changing `y_pred = model(X_trainTensor)` to `y_pred = model(X_trainTensor.float())`.", "Likewise, when you get another error for `loss = loss_fn(y_pred, y_trainTensor)`, you need `y_trainTensor.long()` since the error message says `Expected object of scalar type Long`.", "You could also do `model.double()`, as suggested by @Paddy", ".", ""], "ideal": ["import torch", "from torch import nn", "import numpy as np", "", "def test():", "    x = np.zeros((3,10))", "    x = torch.from_numpy(x).float()", "    model = nn.Sequential(", "        nn.Linear(10, 16),", "        nn.ReLU(),", "        nn.Linear(16, 3),", "        nn.LogSoftmax(dim = 1)", "    )", "    y = model(x)"], "context_url": "https://stackoverflow.com/questions/56741087/how-to-fix-runtimeerror-expected-object-of-scalar-type-float-but-got-scalar-typ", "context_author_url": ["https://stackoverflow.com/users/9642811/milkyway90"]}
{"error": ["Traceback (most recent call last):", "  File \"error.py\", line 25, in <module>", "    test()", "  File \"<string>\", line 4, in test", "AttributeError: module 'urllib' has no attribute 'parse'", ""], "code": ["import urllib", "", "def test():", "    return urllib.parse.quote(\"hello world\", safe='')"], "context": ["", "In Python 3.x, you need to import urllib.parse.quote:", "```", ">>> import urllib.parse", ">>> urllib.parse.quote(\"châteu\", safe='')", "'ch%C3%A2teu'", "```", "", "According to Python 2.x urllib module documentation:", "> ", "> NOTE> ", "> The `urllib` module has been split into parts and renamed in Python 3 to", "  `urllib.request`, `urllib.parse`, and `urllib.error`.> ", "", ""], "ideal": ["import urllib.parse", "", "def test():", "    return urllib.parse.quote(\"hello world\", safe='')"], "context_url": "https://stackoverflow.com/questions/31827012/python-importing-urllib-quote", "context_author_url": ["https://stackoverflow.com/users/2225682/falsetru"]}
{"error": ["Traceback (most recent call last):", "  File \"error.py\", line 29, in <module>", "    test()", "  File \"<string>\", line 7, in test", "  File \"/anaconda/envs/torch13/lib/python3.8/site-packages/sklearn/feature_extraction/text.py\", line 2082, in fit", "    self._validate_params()", "  File \"/anaconda/envs/torch13/lib/python3.8/site-packages/sklearn/base.py\", line 570, in _validate_params", "    validate_parameter_constraints(", "  File \"/anaconda/envs/torch13/lib/python3.8/site-packages/sklearn/utils/_param_validation.py\", line 97, in validate_parameter_constraints", "    raise InvalidParameterError(", "sklearn.utils._param_validation.InvalidParameterError: The 'stop_words' parameter of TfidfVectorizer must be a str among {'english'}, an instance of 'list' or None. Got array(['and', 'the', ',', '.', 'are', 'is', 'or', 'while'], dtype='<U5') instead.", ""], "code": ["from sklearn.feature_extraction.text import TfidfVectorizer", "import numpy as np", "", "def test():", "    word = np.array([\"and\", \"the\", \",\", \".\", \"are\", \"is\", \"or\", \"while\"])", "    tot_data = [\"hello world\", \"I love you\", \"how are you\"]", "    vectorizer = TfidfVectorizer(max_df=.95,stop_words=word).fit(tot_data)"], "context": ["", "Reason: The reason for the error is the fact that numpy array propagates comparaison to elements:", "```", ">>> word == 'english'", "array([False, False, False], dtype=bool)", "```", "", "and `if` statement can't convert resulting array to boolean:", "```", ">>> if word == 'english': pass", "...", "Traceback (most recent call last):", "  File \"<stdin>\", line 1, in <module>", "ValueError: The truth value of an array with more than one element is ambiguous. Use a.any() or a.all()", "```", "", "Solution: Convert words to ordinary list: `words = list(words)`.", "Demo:", "```", ">>> import numpy as np", ">>> from sklearn.feature_extraction.text import TfidfVectorizer", ">>> word = np.array(['one','two','three'])", ">>> tot_data = np.array(['one two three', 'who do I see', 'I see two girls'])", ">>> v = TfidfVectorizer(max_df=.95,stop_words=list(word))", ">>> v.fit(tot_data)", "TfidfVectorizer(analyzer=u'word', binary=False, charset=None,", "   ...", "        tokenizer=None, use_idf=True, vocabulary=None)", "```", "", ""], "ideal": ["from sklearn.feature_extraction.text import TfidfVectorizer", "import numpy as np", "", "def test():", "    word = np.array([\"and\", \"the\", \",\", \".\", \"are\", \"is\", \"or\", \"while\"])", "    tot_data = [\"hello world\", \"I love you\", \"how are you\"]", "    vectorizer = TfidfVectorizer(max_df=.95,stop_words=list(word)).fit(tot_data)"], "context_url": "https://stackoverflow.com/questions/20400454/error-in-scikit-learn-tfidfvectorizer-when-using-the-parameter-stop-words", "context_author_url": ["https://stackoverflow.com/users/1265154/alko"]}
{"error": ["Traceback (most recent call last):", "  File \"error.py\", line 27, in <module>", "    exec(\"\\n\".join(data[\"code\"]))", "  File \"<string>\", line 11", "SyntaxError: cannot assign to operator", ""], "code": ["from sklearn.preprocessing import LabelEncoder", "from sklearn import datasets", "", "", "def test():", "    iris = datasets.load_iris()", "    X = iris.data", "    y = iris.target", "", "    label_encoder = LabelEncoder()", "    target-label = label_encoder.fit_transform(y)"], "context": ["", "This is not an issue related to assigning value to a variable. This is a `Syntax Error`. You haven't followed the proper naming convention to name the variable `play-label`.", "If you try doing something like this :", "```", ">>> a-b = 3", "  File \"<stdin>\", line 1", "SyntaxError: can't assign to operator", "```", "", "You'll get the same error.", "Replace dash `-` with Underscore `_` and it will work fine.", "The correct variable name should be `play_label`.", "Refer to this link, for an indepth description . Python Naming Convention", ""], "ideal": ["from sklearn.preprocessing import LabelEncoder", "from sklearn import datasets", "", "", "def test():", "    iris = datasets.load_iris()", "    X = iris.data", "    y = iris.target", "", "    label_encoder = LabelEncoder()", "    target_label = label_encoder.fit_transform(y)"], "context_url": "https://stackoverflow.com/questions/56832306/why-i-get-cant-assign-to-operator-error", "context_author_url": ["https://stackoverflow.com/users/4685471/desertnaut", "https://stackoverflow.com/users/8911175/taurus05"]}
{"error": ["Traceback (most recent call last):", "  File \"error.py\", line 26, in <module>", "    test()", "  File \"<string>\", line 4, in test", "  File \"/anaconda/envs/torch13/lib/python3.8/site-packages/numpy/__init__.py\", line 311, in __getattr__", "    raise AttributeError(\"module {!r} has no attribute \"", "AttributeError: module 'numpy' has no attribute 'aray'", ""], "code": ["import numpy as np", "", "def test():", "    a = np.aray([[1,2,3,4],[5,6,7,8]])"], "context": ["", "You made a syntax error. Try to write `np.array` instead of `np.aray`", ""], "ideal": ["import numpy as np", "", "def test():", "    a = np.array([[1,2,3,4],[5,6,7,8]])"], "context_url": "https://stackoverflow.com/questions/65549533/attributeerror-traceback-most-recent-call-last-on-python", "context_author_url": ["https://stackoverflow.com/users/13852388/tevfik-sast%c4%b1m"]}
{"error": ["Traceback (most recent call last):", "  File \"error.py\", line 27, in <module>", "    test()", "  File \"<string>\", line 6, in test", "AttributeError: 'AxesSubplot' object has no attribute 'savefig'", ""], "code": ["import seaborn as sns", "", "def test():", "    sns.set_style(\"whitegrid\")", "    ax = sns.barplot(x=list(range(1, 11)), y=list(range(1, 11)), palette=\"Blues_d\")", "    ax.savefig(\"test.png\")"], "context": ["", "I solved the issue by changing ", "```", "ax.savefig('file.png')", "```", "", "to", "```", "ax.figure.savefig('file.png')", "```", "", "I guess accessing the figure directly is one way to get to the `savefig()` method for the barplot. ", "@WoodChopper also has a working solution, but it requires another import statement, and utilizing pyplot's `savefig()` directly. ", "Either solution does require setting `matplotlib.use('Agg')` to get around the DISPLAY variable error. As the referenced post noted, this has to be set before importing other matplotlib libraries. ", ""], "ideal": ["import seaborn as sns", "", "def test():", "    sns.set_style(\"whitegrid\")", "    ax = sns.barplot(x=list(range(1, 11)), y=list(range(1, 11)), palette=\"Blues_d\")", "    ax.figure.savefig(\"test.png\")"], "context_url": "https://stackoverflow.com/questions/33616557/barplot-savefig-returning-an-attributeerror", "context_author_url": ["https://stackoverflow.com/users/-1/community", "https://stackoverflow.com/users/3902926/economy"]}
{"error": ["Traceback (most recent call last):", "  File \"error.py\", line 25, in <module>", "    test()", "  File \"<string>\", line 2, in test", "TypeError: not enough arguments for format string", ""], "code": ["def test():", "    return \"%s %s\" % \"hello\", \"world\""], "context": ["", "Note that the `%` syntax for formatting strings is becoming outdated. If your version of Python supports it, you should write:", "```", "instr = \"'{0}', '{1}', '{2}', '{3}', '{4}', '{5}', '{6}'\".format(softname, procversion, int(percent), exe, description, company, procurl)", "```", "", "This also fixes the error that you happened to have.", ""], "ideal": ["def test():", "    return \"%s %s\" % (\"hello\", \"world\")"], "context_url": "https://stackoverflow.com/questions/11146190/python-typeerror-not-enough-arguments-for-format-string", "context_author_url": ["https://stackoverflow.com/users/1267329/simeon-visser"]}
{"error": ["Traceback (most recent call last):", "  File \"test.py\", line 53, in <module>", "    test()", "  File \"test.py\", line 4, in test", "    response = urllib.request.urlopen(\"https://www.google.com\")", "AttributeError: module 'urllib' has no attribute 'request'"], "code": ["import urllib", "", "def test():", "    response = urllib.request.urlopen(\"https://www.google.com\")", "    return response"], "context": ["According to this, you have to use the following:", "```", "import urllib.request", "```", "The reason is:", "> With packages, like this, you sometimes need to explicitly import the piece you want. That way, the urllib module doesn't have to load everything up just because you wanted one small part."], "ideal": ["import urllib.request", "", "def test():", "    response = urllib.request.urlopen(\"https://www.google.com\")", "    return response"], "context_url": "https://stackoverflow.com/questions/37042152/python-3-5-1-urllib-has-no-attribute-request", "context_author_url": ["https://stackoverflow.com/users/3961903/galoget", "https://stackoverflow.com/users/2741080/swordsman"]}
{"error": ["Traceback (most recent call last):", "  File \"error.py\", line 22, in <module>", "    test()", "  File \"<string>\", line 8, in test", "AttributeError: Can't pickle local object 'test.<locals>.MyClass'", ""], "code": ["import pickle", "", "def test():", "    class MyClass:", "        def __init__(self):", "            self.name = \"my_cls\"", "", "    pickle.dumps(MyClass())"], "context": ["", "Multiprocessing uses pickle to serialize and transfer data between sub-processes.", "Pickle cannot serialize local (inner) functions. Try setting your `target` to a function visible from the file's namespace.", "For example:", "```", "import multiprocessing", "", "", "def abc(self):", "", "    try:", "        \"\"\"Some", "            logic", "            here\"\"\"", "", "", "    except Exception as E:", "        print('Error : ', E)", "", "def func1(sfunc1):", "", "    \"\"\"some", "    logic", "    here\"\"\"", "", "def func2(sfunc2):", "", "    \"\"\"some", "    logic", "    here\"\"\"", "", "def check(stk):", "", "    p1 = multiprocessing.Process(target=func1, args=s1)  # s1 and s2 is a List", "    p2 = multiprocessing.Process(target=func2, args=s2)", "    p1.start()", "    p2.start()", "    p1.join()", "    p2.join()", "", "if __name__ == \"__main__\":  # Make sure only 1 process runs this.", "    check(Symbols)", "```", "", "Make sure `s1`, `s2`, and `Symbols` are defined.", ""], "ideal": ["import pickle", "", "class MyClass:", "    def __init__(self):", "        self.name = \"my_cls\"", "", "def test():", "    pickle.dumps(MyClass())"], "context_url": "https://stackoverflow.com/questions/70422581/python-multiprocessing-basic-cant-pickle-local-object-and-ran-out-of-input", "context_author_url": ["https://stackoverflow.com/users/1658617/bharel"]}
{"error": ["Traceback (most recent call last):", "  File \"error.py\", line 26, in <module>", "    test()", "  File \"<string>\", line 4, in test", "ValueError: could not convert string to float: 'abc'", ""], "code": ["import numpy as np", "", "def test():", "    arr = np.array([1.2, \"abc\"], dtype=float)", "    return arr"], "context": ["", "Possible reason 1: trying to create a jagged array", "You may be creating an array from a list that isn't shaped like a multi-dimensional array:", "```", "numpy.array([[1, 2], [2, 3, 4]])         # wrong!", "```", "", "```", "numpy.array([[1, 2], [2, [3, 4]]])       # wrong!", "```", "", "In these examples, the argument to `numpy.array` contains sequences of different lengths. Those will yield this error message because the input list is not shaped like a \"box\" that can be turned into a multidimensional array.", "Possible reason 2: providing elements of incompatible types", "For example, providing a string as an element in an array of type `float`:", "```", "numpy.array([1.2, \"abc\"], dtype=float)   # wrong!", "```", "", "If you really want to have a NumPy array containing both strings and floats, you could use the dtype `object`, which allows the array to hold arbitrary Python objects:", "```", "numpy.array([1.2, \"abc\"], dtype=object)", "```", "", ""], "ideal": ["import numpy as np", "", "def test():", "    arr = np.array([1.2, \"abc\"], dtype=object)", "    return arr"], "context_url": "https://stackoverflow.com/questions/4674473/valueerror-setting-an-array-element-with-a-sequence", "context_author_url": ["https://stackoverflow.com/users/365102/mateen-ulhaq", "https://stackoverflow.com/users/279627/sven-marnach"]}
{"error": ["Traceback (most recent call last):", "  File \"error.py\", line 23, in <module>", "    exec(\"\\n\".join(data[\"code\"]))", "  File \"<string>\", line 1, in <module>", "  File \"<string>\", line 3, in MyCLS", "  File \"<string>\", line 3, in <lambda>", "NameError: name 'mul_list' is not defined", ""], "code": ["class MyCLS:", "    mul_list = [1, 11, 32]", "    precmp_list = list(map(lambda x: {k: x * k for k in mul_list}, range(100)))", "", "my_cls = MyCLS()"], "context": ["", "You probably want to put some of this code into a constructor. As written, it's all defined as part of the class, which is causing your problem: `count_mon` isn't in scope when the `lambda` function is called.", "Move this code inside an `__init__` function:", "```", "class Week(): ", "    def __init__(self):", "        blank_mon=[0]*24", "        sum_mon=blank_mon", "        count_mon=0", "", "        print (\"Blank Monday: \",blank_mon)", "        #curr_mon=[1,0,2,0,3,0,4,0,5,0,3,0,3,0,2,0,1,0,2,0,1,0,1,0]", "        curr_mon=[1,2,3,4,5,6,7,8,9,10,11,12,13,14,15,16,17,18,19,20,21,22,23,24]", "        print (\"Current Monday\",curr_mon)", "        count_mon = count_mon + 1", "        print (\"Monday Count:\",count_mon)", "        sum_mon=list(map(add,sum_mon,curr_mon))                   #Adds all the Mondays together for each hour", "        print (\"Total sum of all Mondays::\",sum_mon)", "        avg_mon = list(map(lambda w_mon: float(w_mon)/count_mon,sum_mon))   #Gets the average of the Mondays for each hour", "        print (\"Average Monday::\",avg_mon)", "```", "", "Here's the full explanation for why this happens: Accessing class variables from a list comprehension in the class definition", ""], "ideal": ["class MyCLS:", "    def __init__(self):", "        self.mul_list = [1, 11, 32]", "        self.precmp_list = list(map(lambda x: {k: x * k for k in self.mul_list}, range(100)))", "", "my_cls = MyCLS()"], "context_url": "https://stackoverflow.com/questions/43840250/python-class-lambda-name-error-name-not-defined", "context_author_url": ["https://stackoverflow.com/users/-1/community", "https://stackoverflow.com/users/1342257/nikolas-stevenson-molnar"]}
{"error": ["Traceback (most recent call last):", "  File \"error.py\", line 29, in <module>", "    test()", "  File \"<string>\", line 6, in test", "  File \"/anaconda/envs/torch13/lib/python3.8/site-packages/pandas/core/generic.py\", line 1527, in __nonzero__", "    raise ValueError(", "ValueError: The truth value of a Series is ambiguous. Use a.empty, a.bool(), a.item(), a.any() or a.all().", ""], "code": ["import pandas as pd", "import numpy as np", "", "def test():", "    s = pd.Series(np.random.randn(100))    ", "    s = s[(s < -0.25) or (s > 0.25)]", "    return s"], "context": ["", "The `or` and `and` Python statements require truth-values. For pandas, these are considered ambiguous, so you should use \"bitwise\" `|` (or) or `&` (and) operations:", "```", "df = df[(df['col'] < -0.25) | (df['col'] > 0.25)]", "```", "", "These are overloaded for these kinds of data structures to yield the element-wise `or` or `and`.", "", "Just to add some more explanation to this statement:", "The exception is thrown when you want to get the `bool` of a `pandas.Series`:", "```", ">>> import pandas as pd", ">>> x = pd.Series([1])", ">>> bool(x)", "ValueError: The truth value of a Series is ambiguous. Use a.empty, a.bool(), a.item(), a.any() or a.all().", "```", "", "You hit a place where the operator implicitly converted the operands to `bool` (you used `or` but it also happens for `and`, `if` and `while`):", "```", ">>> x or x", "ValueError: The truth value of a Series is ambiguous. Use a.empty, a.bool(), a.item(), a.any() or a.all().", ">>> x and x", "ValueError: The truth value of a Series is ambiguous. Use a.empty, a.bool(), a.item(), a.any() or a.all().", ">>> if x:", "...     print('fun')", "ValueError: The truth value of a Series is ambiguous. Use a.empty, a.bool(), a.item(), a.any() or a.all().", ">>> while x:", "...     print('fun')", "ValueError: The truth value of a Series is ambiguous. Use a.empty, a.bool(), a.item(), a.any() or a.all().", "```", "", "Besides these four statements, there are several Python functions that hide some `bool` calls (like `any`, `all`, `filter`, ...). These are normally not problematic with `pandas.Series`, but for completeness I wanted to mention these.", "", "In your case, the exception isn't really helpful, because it doesn't mention the right alternatives. For `and` and `or`, if you want element-wise comparisons, you can use:", "", "numpy.logical_or:", ">>> import numpy as np", ">>> np.logical_or(x, y)", "", "or simply the | operator:", ">>> x | y", "", "", "numpy.logical_and:", ">>> np.logical_and(x, y)", "", "or simply the & operator:", ">>> x & y", "", "", "", "If you're using the operators, then be sure to set your parentheses correctly because of operator precedence.", "There are several logical NumPy functions which should work on `pandas.Series`.", "", "The alternatives mentioned in the Exception are more suited if you encountered it when doing `if` or `while`. I'll shortly explain each of these:", "", "If you want to check if your Series is empty:", ">>> x = pd.Series([])", ">>> x.empty", "True", ">>> x = pd.Series([1])", ">>> x.empty", "False", "", "Python normally interprets the length of containers (like list, tuple, ...) as truth-value if it has no explicit Boolean interpretation. So if you want the Python-like check, you could do: if x.size or if not x.empty instead of if x.", "", "If your Series contains one and only one Boolean value:", ">>> x = pd.Series([100])", ">>> (x > 50).bool()", "True", ">>> (x < 50).bool()", "False", "", "", "If you want to check the first and only item of your Series (like .bool(), but it works even for non-Boolean contents):", ">>> x = pd.Series([100])", ">>> x.item()", "100", "", "", "If you want to check if all or any item is not-zero, not-empty or not-False:", ">>> x = pd.Series([0, 1, 2])", ">>> x.all()   # Because one element is zero", "False", ">>> x.any()   # because one (or more) elements are non-zero", "True", "", "", "", ""], "ideal": ["import pandas as pd", "import numpy as np", "", "def test():", "    s = pd.Series(np.random.randn(100))    ", "    s = s[(s < -0.25) | (s > 0.25)]", "    return s"], "context_url": "https://stackoverflow.com/questions/36921951/truth-value-of-a-series-is-ambiguous-use-a-empty-a-bool-a-item-a-any-o?rq=1", "context_author_url": ["https://stackoverflow.com/users/63550/peter-mortensen", "https://stackoverflow.com/users/5393381/mseifert"]}
{"error": ["Traceback (most recent call last):", "  File \"error.py\", line 29, in <module>", "    test()", "  File \"<string>\", line 8, in test", "AssertionError: Value not changed", ""], "code": ["import pandas as pd", "", "def test():", "    data = {\"a\": [1, 2, 4], \"b\": [4, 5, 6]}", "    df = pd.DataFrame.from_dict(data)", "", "    df[df[\"a\"] == 1][\"b\"] = 5", "    assert df[df[\"a\"] == 1][\"b\"].item() == 5, \"Value not changed\""], "context": ["", "The `SettingWithCopyWarning` was created to flag potentially confusing \"chained\" assignments, such as the following, which does not always work as expected, particularly when the first selection returns a copy.  [see GH5390 and GH5597 for background discussion.]", "```", "df[df['A'] > 2]['B'] = new_val  # new_val not set in df", "```", "", "The warning offers a suggestion to rewrite as follows:", "```", "df.loc[df['A'] > 2, 'B'] = new_val", "```", "", "However, this doesn't fit your usage, which is equivalent to:", "```", "df = df[df['A'] > 2]", "df['B'] = new_val", "```", "", "While it's clear that you don't care about writes making it back to the original frame (since you are overwriting the reference to it), unfortunately this pattern cannot be differentiated from the first chained assignment example. Hence the (false positive) warning. The potential for false positives is addressed in the docs on indexing, if you'd like to read further.  You can safely disable this new warning with the following assignment.", "```", "import pandas as pd", "pd.options.mode.chained_assignment = None  # default='warn'", "```", "", "", "Other Resources", "", "pandas User Guide: Indexing and selecting data", "Python Data Science Handbook: Data Indexing and Selection", "Real Python: SettingWithCopyWarning in Pandas: Views vs Copies", "Dataquest: SettingwithCopyWarning: How to Fix This Warning in Pandas", "Towards Data Science: Explaining the SettingWithCopyWarning in pandas", "", ""], "ideal": ["import pandas as pd", "", "def test():", "    data = {\"a\": [1, 2, 4], \"b\": [4, 5, 6]}", "    df = pd.DataFrame.from_dict(data)", "", "    df.loc[df[\"a\"] == 1, \"b\"] = 5", "    assert df[df[\"a\"] == 1][\"b\"].item() == 5, \"Value not changed\""], "context_url": "https://stackoverflow.com/questions/20625582/how-to-deal-with-settingwithcopywarning-in-pandas", "context_author_url": ["https://stackoverflow.com/users/7758804/trenton-mckinney", "https://stackoverflow.com/users/243434/garrett"]}
{"error": ["Traceback (most recent call last):", "  File \"error.py\", line 22, in <module>", "    test()", "  File \"<string>\", line 5, in test", "  File \"/anaconda/envs/torch13/lib/python3.8/json/__init__.py\", line 231, in dumps", "    return _default_encoder.encode(obj)", "  File \"/anaconda/envs/torch13/lib/python3.8/json/encoder.py\", line 199, in encode", "    chunks = self.iterencode(o, _one_shot=True)", "  File \"/anaconda/envs/torch13/lib/python3.8/json/encoder.py\", line 257, in iterencode", "    return _iterencode(o, 0)", "  File \"/anaconda/envs/torch13/lib/python3.8/json/encoder.py\", line 179, in default", "    raise TypeError(f'Object of type {o.__class__.__name__} '", "TypeError: Object of type set is not JSON serializable", ""], "code": ["import json", "", "class MyClass:", "    def __init__(self):", "        self.name = \"my_cls\"", "", "def test():", "    json.dumps(MyClass())"], "context": ["", "The basic problem is that the JSON encoder `json.dumps()` only knows how to serialize a limited set of object types by default, all built-in types.  List here: https://docs.python.org/3.3/library/json.html#encoders-and-decoders", "One good solution would be to make your class inherit from `JSONEncoder` and then implement the `JSONEncoder.default()` function, and make that function emit the correct JSON for your class.", "A simple solution would be to call `json.dumps()` on the `.__dict__` member of that instance.  That is a standard Python `dict` and if your class is simple it will be JSON serializable.", "```", "class Foo(object):", "    def __init__(self):", "        self.x = 1", "        self.y = 2", "", "foo = Foo()", "s = json.dumps(foo) # raises TypeError with \"is not JSON serializable\"", "", "s = json.dumps(foo.__dict__) # s set to: {\"x\":1, \"y\":2}", "```", "", "The above approach is discussed in this blog posting:", "    Serializing arbitrary Python objects to JSON using _dict_", "And, of course, Python offers a built-in function that accesses `.__dict__` for you, called `vars()`.", "So the above example can also be done as:", "```", "s = json.dumps(vars(foo)) # s set to: {\"x\":1, \"y\":2}", "```", "", ""], "ideal": ["import json", "", "class MyClass:", "    def __init__(self):", "        self.name = \"my_cls\"", "", "def test():", "    json.dumps(MyClass().__dict__)"], "context_url": "https://stackoverflow.com/questions/10252010/serializing-class-instance-to-json", "context_author_url": ["https://stackoverflow.com/users/166949/steveha"]}
{"error": ["/anaconda/envs/torch13/lib/python3.8/site-packages/sklearn/metrics/_classification.py:1344: UndefinedMetricWarning: Precision and F-score are ill-defined and being set to 0.0 in labels with no predicted samples. Use `zero_division` parameter to control this behavior._warn_prf(average, modifier, msg_start, len(result))"], "code": ["import sklearn.metrics as metrics", "", "def test():", "    y_true = [0, 1, 2, 0, 1, 2]", "    y_pred = [1, 1, 1, 1, 1, 1]", "    rslt = metrics.precision_recall_fscore_support(y_true, y_pred, average=\"weighted\")", "    return rslt"], "context": ["", "As mentioned in the comments, some labels in `y_test` don't appear in `y_pred`. Specifically in this case, label '2' is never predicted:", "```", ">>> set(y_test) - set(y_pred)", "{2}", "```", "", "This means that there is no F-score to calculate for this label, and thus the F-score for this case is considered to be 0.0. Since you requested an average of the score, you must take into account that a score of 0 was included in the calculation, and this is why scikit-learn is showing you that warning.", "This brings me to you not seeing the error a second time. As I mentioned, this is a warning, which is treated differently from an error in python. The default behavior in most environments is to show a specific warning only once. This behavior can be changed:", "```", "import warnings", "warnings.filterwarnings('always')  # \"error\", \"ignore\", \"always\", \"default\", \"module\" or \"once\"", "```", "", "If you set this before importing the other modules, you will see the warning every time you run the code.", "There is no way to avoid seeing this warning the first time, aside for setting `warnings.filterwarnings('ignore')`. What you can do, is decide that you are not interested in the scores of labels that were not predicted, and then explicitly specify the labels you are interested in (which are labels that were predicted at least once):", "```", ">>> metrics.f1_score(y_test, y_pred, average='weighted', labels=np.unique(y_pred))", "0.91076923076923078", "```", "", "The warning will be gone.", ""], "ideal": ["import sklearn.metrics as metrics", "import numpy as np", "", "def test():", "    y_true = [0, 1, 2, 0, 1, 2]", "    y_pred = [1, 1, 1, 1, 1, 1]", "    rslt = metrics.precision_recall_fscore_support(y_true, y_pred, average=\"weighted\", labels=np.unique(y_pred))", "    return rslt"], "context_url": "https://stackoverflow.com/questions/43162506/undefinedmetricwarning-f-score-is-ill-defined-and-being-set-to-0-0-in-labels-wi", "context_author_url": ["https://stackoverflow.com/users/3907250/aerin", "https://stackoverflow.com/users/4983290/shovalt"]}
{"error": ["Traceback (most recent call last):", "  File \"error.py\", line 25, in <module>", "    test()", "TypeError: test() missing 1 required positional argument: 'name'", ""], "code": ["import threading", "", "def hello(name):", "    print(\"hello \" + name)", "", "processThread = threading.Thread(target=hello, args=(\"Alice\")) ", "processThread.start()", "", "processThread = threading.Thread(target=hello, args=(\"Tome\"))", "processThread.start()"], "context": ["", "You're trying to create a tuple, but you're just parenthesizing a string :)", "Add an extra ',': ", "```", "dRecieved = connFile.readline()", "processThread = threading.Thread(target=processLine, args=(dRecieved,))  # <- note extra ','", "processThread.start()", "```", "", "Or use brackets to make a list:", "```", "dRecieved = connFile.readline()", "processThread = threading.Thread(target=processLine, args=[dRecieved])  # <- 1 element list", "processThread.start()", "```", "", "", "If you notice, from the stack trace: `self.__target(*self.__args, **self.__kwargs)`", "The `*self.__args` turns your string into a list of characters, passing them to the `processLine`", "function.  If you pass it a one element list, it will pass that element as the first argument - in your case, the string.", ""], "ideal": ["import threading", "", "def hello(name):", "    print(\"hello \" + name)", "", "processThread = threading.Thread(target=hello, args=(\"Alice\",)) ", "processThread.start()", "", "processThread = threading.Thread(target=hello, args=(\"Tome\",))", "processThread.start()"], "context_url": "https://stackoverflow.com/questions/3221655/why-doesnt-a-string-in-parentheses-make-a-tuple-with-just-that-string", "context_author_url": ["https://stackoverflow.com/users/14569/davr", "https://stackoverflow.com/users/303180/stephen"]}
{"error": ["Traceback (most recent call last):", "  File \"error.py\", line 25, in <module>", "    test()", "  File \"<string>\", line 6, in test", "TypeError: 'NoneType' object is not iterable", ""], "code": ["def test():", "    inputs = [\"100\", \"apple\", [1, 2, 3, 4], None]", "", "    rslts = []", "    for i in inputs:", "        rslt = set(i)", "        rslts.append(rslt)", "    return rslts"], "context": ["", "As the error message tells you, `set()` expects an iterable.", "```", "set([None])", "```", "", "Note: the same is true for `list`, `tuple`, ...", ""], "ideal": ["def test():", "    inputs = [\"100\", \"apple\", [1, 2, 3, 4], [None]]", "", "    rslts = []", "    for i in inputs:", "        rslt = set(i)", "        rslts.append(rslt)", "    return rslts"], "context_url": "https://stackoverflow.com/questions/7719419/why-is-setnone-invalid-in-python", "context_author_url": ["https://stackoverflow.com/users/650405/karoly-horvath"]}
{"error": ["Traceback (most recent call last):", "  File \"error.py\", line 26, in <module>", "    test()", "  File \"<string>\", line 7, in test", "  File \"<__array_function__ internals>\", line 180, in concatenate", "ValueError: zero-dimensional arrays cannot be concatenated", ""], "code": ["from scipy import sparse", "import numpy as np", "", "def test():", "    x1 = sparse.eye(3)", "    x2 = sparse.eye(3)", "    x = np.concatenate((x1,x2))"], "context": ["", "Applying `np.concatenate` to `scipy` `sparse` matrices produces this error:", "```", "In [162]: from scipy import sparse", "In [163]: x=sparse.eye(3)", "In [164]: x", "Out[164]: ", "<3x3 sparse matrix of type '<class 'numpy.float64'>'", "    with 3 stored elements (1 diagonals) in DIAgonal format>", "In [165]: np.concatenate((x,x))", "---------------------------------------------------------------------------", "ValueError                                Traceback (most recent call last)", "<ipython-input-165-0b67d0029ca6> in <module>()", "----> 1 np.concatenate((x,x))", "", "ValueError: zero-dimensional arrays cannot be concatenated", "```", "", "There are `sparse` functions to do this:", "```", "In [168]: sparse.hstack((x,x)).A", "Out[168]: ", "array([[ 1.,  0.,  0.,  1.,  0.,  0.],", "       [ 0.,  1.,  0.,  0.,  1.,  0.],", "       [ 0.,  0.,  1.,  0.,  0.,  1.]])", "In [169]: sparse.vstack((x,x)).A", "Out[169]: ", "array([[ 1.,  0.,  0.],", "       [ 0.,  1.,  0.],", "       [ 0.,  0.,  1.],", "       [ 1.,  0.,  0.],", "       [ 0.,  1.,  0.],", "       [ 0.,  0.,  1.]])", "```", "", ""], "ideal": ["from scipy import sparse", "import numpy as np", "", "def test():", "    x1 = sparse.eye(3)", "    x2 = sparse.eye(3)", "    x = sparse.hstack((x1,x2)).A"], "context_url": "https://stackoverflow.com/questions/36415811/numpy-error-while-concatenation-zero-dimensional-arrays-cannot-be-concatenate", "context_author_url": ["https://stackoverflow.com/users/901925/hpaulj"]}
{"error": ["AttributeError: 'int' object has no attribute 'sqrt'", "", "The above exception was the direct cause of the following exception:", "", "Traceback (most recent call last):", "  File \"error.py\", line 26, in <module>", "    test()", "  File \"<string>\", line 5, in test", "TypeError: loop of ufunc does not support argument 0 of type int which has no callable sqrt method", ""], "code": ["import numpy as np", "", "def test():", "    print(np.sqrt(2 ** 64 - 1))", "    print(np.sqrt(2 ** 64))"], "context": ["", "I'll try to add a precise answer to those that have already been given. `numpy.sqrt` has some limitations that `math.sqrt` doesn't have.", "```", "import math", "import numpy  # version 1.13.3", "", "print(math.sqrt(2 ** 64 - 1))", "print(numpy.sqrt(2 ** 64 - 1))", "", "print(math.sqrt(2 ** 64))", "print(numpy.sqrt(2 ** 64))", "```", "", "returns (with Python 3.5) :", "```", "4294967296.0", "4294967296.0", "4294967296.0", "Traceback (most recent call last):", "  File \"main.py\", line 8, in <module>", "    print(numpy.sqrt(2 ** 64))", "AttributeError: 'int' object has no attribute 'sqrt'", "```", "", "In fact, `2 ** 64` is equal to `18,446,744,073,709,551,616` and, according to the standard of C data types (version C99), the `long long unsigned integer` type contains at least the range between `0` and `18,446,744,073,709,551,615` included.", "The `AttributeError` occurs because `numpy`, seeing a type that it doesn't know how to handle (after conversion to C data type), defaults to calling the `sqrt` method on the object (but that doesn't exist). If we use floats instead of integers then everything will work using `numpy`:", "```", "import numpy  # version 1.13.3", "", "print(numpy.sqrt(float(2 ** 64)))", "```", "", "returns:", "```", "4294967296.0", "```", "", "So instead of replacing `numpy.sqrt` by `math.sqrt`, you can alternatively replace `calc = np.sqrt(food ** 5)` by `calc = np.sqrt(float(food ** 5))` in your code.", "I hope this error will make more sense to you now.", ""], "ideal": ["import numpy as np", "", "def test():", "    print(np.sqrt(float(2 ** 64 - 1)))", "    print(np.sqrt(float(2 ** 64)))"], "context_url": "https://stackoverflow.com/questions/47123035/python-error-when-calling-numpy-from-class-method-with-map", "context_author_url": ["https://stackoverflow.com/users/2225883/flabetvibes"]}
{"error": ["Traceback (most recent call last):", "  File \"error.py\", line 22, in <module>", "    test()", "  File \"<string>\", line 14, in test", "TypeError: file must have 'read' and 'readline' attributes", ""], "code": ["import zlib", "import pickle", "", "def test():", "    mydict = [", "        {\"name\": \"alice\", \"age\": 17},", "        {\"name\": \"mike\", \"age\": 21}", "    ]", "", "    with open(\"test.gz\", \"wb\") as f:", "        f.write(zlib.compress(pickle.dumps(mydict)))", "    ", "    with open(\"test.gz\", \"rb\") as f:", "        my_dict = pickle.load(zlib.decompress(f.read()))", "    ", "    return my_dict"], "context": ["", "The errors you are getting on attempts 3-5 are because you're using `pickle.load` instead of `pickle.loads`. The former expects a file-like object, rather than the byte string you're getting from the decompression calls.", "This will work:", "```", "with open('test.gz', 'rb') as fp:", "    data = zlib.decompress(fp.read())", "    successDict = pickle.loads(data)", "```", "", ""], "ideal": ["import zlib", "import pickle", "", "def test():", "    mydict = [", "        {\"name\": \"alice\", \"age\": 17},", "        {\"name\": \"mike\", \"age\": 21}", "    ]", "", "    with open(\"test.gz\", \"wb\") as f:", "        f.write(zlib.compress(pickle.dumps(mydict)))", "    ", "    with open(\"test.gz\", \"rb\") as f:", "        my_dict = pickle.loads(zlib.decompress(f.read()))", "    ", "    return my_dict"], "context_url": "https://stackoverflow.com/questions/12242805/using-zlib-and-cpickle-to-compress-decompress-a-dictionary-to-files", "context_author_url": ["https://stackoverflow.com/users/1405065/blckknght"]}
{"error": ["Traceback (most recent call last):", "  File \"error.py\", line 20, in <module>", "    exec(\"\\n\".join(data[\"code\"]))", "  File \"<string>\", line 10, in <module>", "  File \"/anaconda/envs/torch13/lib/python3.8/multiprocessing/pool.py\", line 364, in map", "    return self._map_async(func, iterable, mapstar, chunksize).get()", "  File \"/anaconda/envs/torch13/lib/python3.8/multiprocessing/pool.py\", line 771, in get", "    raise self._value", "  File \"/anaconda/envs/torch13/lib/python3.8/multiprocessing/pool.py\", line 537, in _handle_tasks", "    put(task)", "  File \"/anaconda/envs/torch13/lib/python3.8/multiprocessing/connection.py\", line 206, in send", "    self._send_bytes(_ForkingPickler.dumps(obj))", "  File \"/anaconda/envs/torch13/lib/python3.8/multiprocessing/reduction.py\", line 51, in dumps", "    cls(buf, protocol).dump(obj)", "  File \"/anaconda/envs/torch13/lib/python3.8/multiprocessing/queues.py\", line 58, in __getstate__", "    context.assert_spawning(self)", "  File \"/anaconda/envs/torch13/lib/python3.8/multiprocessing/context.py\", line 359, in assert_spawning", "    raise RuntimeError(", "RuntimeError: Queue objects should only be shared between processes through inheritance", ""], "code": ["import multiprocessing as mp", "from multiprocessing import Queue", "from functools import partial", "", "def put(name, queue):", "    queue.put(name)", "", "queue = Queue()", "pool = mp.Pool(processes=3)", "map_result = pool.map(partial(put, queue=queue), range(5))", "", "", "while not queue.empty():", "    if queue.empty():", "        break", "    print(queue.get())"], "context": ["", "Try using multiprocessing.Manager to manage your queue and to also make it accessible to different workers.", "```", "import multiprocessing", "def worker(name, que):", "    que.put(\"%d is done\" % name)", "", "if __name__ == '__main__':", "    pool = multiprocessing.Pool(processes=3)", "    m = multiprocessing.Manager()", "    q = m.Queue()", "    workers = pool.apply_async(worker, (33, q))", "```", "", ""], "ideal": ["import multiprocessing as mp", "from multiprocessing import Queue", "from functools import partial", "", "def put(name, queue):", "    queue.put(name)", "", "m = mp.Manager()", "queue = m.Queue()", "pool = mp.Pool(processes=3)", "map_result = pool.map(partial(put, queue=queue), range(5))", "", "", "while not queue.empty():", "    if queue.empty():", "        break", "    print(queue.get())"], "context_url": "https://stackoverflow.com/questions/9908781/sharing-a-result-queue-among-several-processes", "context_author_url": ["https://stackoverflow.com/users/699305/alexis", "https://stackoverflow.com/users/585339/enderskill"]}
{"error": ["Traceback (most recent call last):", "  File \"error.py\", line 24, in <module>", "    test()", "  File \"<string>\", line 28, in test", "  File \"/anaconda/envs/torch13/lib/python3.8/site-packages/torch/jit/_trace.py\", line 1175, in _get_trace_graph", "    outs = ONNXTracedModule(f, strict, _force_outplace, return_inputs, _return_inputs_states)(*args, **kwargs)", "  File \"/anaconda/envs/torch13/lib/python3.8/site-packages/torch/nn/modules/module.py\", line 1130, in _call_impl", "    return forward_call(*input, **kwargs)", "  File \"/anaconda/envs/torch13/lib/python3.8/site-packages/torch/jit/_trace.py\", line 127, in forward", "    graph, out = torch._C._create_graph_by_tracing(", "  File \"/anaconda/envs/torch13/lib/python3.8/site-packages/torch/jit/_trace.py\", line 118, in wrapper", "    outs.append(self.inner(*trace_inputs))", "  File \"/anaconda/envs/torch13/lib/python3.8/site-packages/torch/nn/modules/module.py\", line 1130, in _call_impl", "    return forward_call(*input, **kwargs)", "  File \"/anaconda/envs/torch13/lib/python3.8/site-packages/torch/nn/modules/module.py\", line 1118, in _slow_forward", "    result = self.forward(*input, **kwargs)", "  File \"<string>\", line 18, in forward", "RuntimeError: shape '[-1, 400]' is invalid for input of size 384", ""], "code": ["import torch", "from torch import nn", "import torch.nn.functional as F", "", "class Net(nn.Module):", "    def __init__(self):", "        super(Net, self).__init__()", "        self.conv1 = nn.Conv2d(3, 6, 5)", "        self.pool = nn.MaxPool2d(2, 2)", "        self.conv2 = nn.Conv2d(6, 16, 5)", "        self.fc1 = nn.Linear(16*5*5, 120)", "        self.fc2 = nn.Linear(120, 84)", "        self.fc3 = nn.Linear(84, 10)", "", "    def forward(self, x):", "        x = self.pool(F.relu(self.conv1(x)))", "        x = self.pool(F.relu(self.conv2(x)))", "        x = x.view(-1, 16*5*5)", "        x = F.relu(self.fc1(x))", "        x = F.relu(self.fc2(x))", "        x = self.fc3(x)", "        return x", "", "def test():", "    model = Net().cuda()", "    input_shape = (3, 21,21)", "    dummy_input = torch.randn(6,*input_shape).cuda()", "    graph = torch.jit._get_trace_graph(model,  args=dummy_input, _force_outplace=False, _return_inputs_states=False)"], "context": ["", "The shape of the tensor after the convolutional layers is [6,16,2,2]. So you cannot reshape it to 16*5*5 before feeding them to the linear layers. You should change your network to the one given below if you want to use the same filter sizes as the original in the convolutional layers.", "```", "class Net(nn.Module):", "    def __init__(self):", "        super(Net, self).__init__()", "        self.conv1 = nn.Conv2d(3, 6, 5)", "        self.pool = nn.MaxPool2d(2, 2)", "        self.conv2 = nn.Conv2d(6, 16, 5)", "        self.fc1 = nn.Linear(16*2*2, 120) # changed the size", "        self.fc2 = nn.Linear(120, 84)", "        self.fc3 = nn.Linear(84, 10)", "", "    def forward(self, x):", "        x = self.pool(F.relu(self.conv1(x)))", "        x = self.pool(F.relu(self.conv2(x)))", "        x = x.view(-1, 16*2*2) # changed the size", "        x = F.relu(self.fc1(x))", "        x = F.relu(self.fc2(x))", "        x = self.fc3(x)", "        return x", "```", "", ""], "ideal": ["import torch", "from torch import nn", "import torch.nn.functional as F", "", "class Net(nn.Module):", "    def __init__(self):", "        super(Net, self).__init__()", "        self.conv1 = nn.Conv2d(3, 6, 5)", "        self.pool = nn.MaxPool2d(2, 2)", "        self.conv2 = nn.Conv2d(6, 16, 5)", "        self.fc1 = nn.Linear(16*2*2, 120)", "        self.fc2 = nn.Linear(120, 84)", "        self.fc3 = nn.Linear(84, 10)", "", "    def forward(self, x):", "        x = self.pool(F.relu(self.conv1(x)))", "        x = self.pool(F.relu(self.conv2(x)))", "        x = x.view(-1, 16*2*2)", "        x = F.relu(self.fc1(x))", "        x = F.relu(self.fc2(x))", "        x = self.fc3(x)", "        return x", "", "def test():", "    model = Net().cuda()", "    input_shape = (3, 21,21)", "    dummy_input = torch.randn(6,*input_shape).cuda()", "    graph = torch.jit._get_trace_graph(model,  args=dummy_input, _force_outplace=False, _return_inputs_states=False)"], "context_url": "https://stackoverflow.com/questions/61794587/runtime-error-shape-is-invalid-for-input", "context_author_url": ["https://stackoverflow.com/users/8421999/nsidn98"]}
{"error": ["Traceback (most recent call last):", "  File \"error.py\", line 27, in <module>", "    test()", "  File \"<string>\", line 10, in test", "  File \"/anaconda/envs/torch13/lib/python3.8/site-packages/matplotlib/pyplot.py\", line 2061, in colorbar", "    raise RuntimeError('No mappable was found to use for colorbar '", "RuntimeError: No mappable was found to use for colorbar creation. First define a mappable such as an image (with imshow) or a contour set (with contourf).", ""], "code": ["from matplotlib import pylab as pl", "import numpy as np", "", "def test():", "    data = np.random.rand(6,6)", "    fig = pl.figure(1)", "    fig.clf()", "    ax = fig.add_subplot(1,1,1)", "    ax.imshow(data, interpolation='nearest', vmin=0.5, vmax=0.99)", "    pl.colorbar()", "", "    pl.show()"], "context": ["", "Note: I am using python 2.6.2. The same error was raised with your code and the following modification solved the problem.", "I read the following colorbar example: http://matplotlib.sourceforge.net/examples/pylab_examples/colorbar_tick_labelling_demo.html", "```", "from matplotlib import pylab as pl", "import numpy as np", "", "data = np.random.rand(6,6)", "fig = pl.figure(1)", "fig.clf()", "ax = fig.add_subplot(1,1,1)", "img = ax.imshow(data, interpolation='nearest', vmin=0.5, vmax=0.99)", "fig.colorbar(img)", "", "pl.show()", "```", "", "Not sure why your example didn't work. I'm not that familiar with matplotlib.", ""], "ideal": ["from matplotlib import pylab as pl", "import numpy as np", "", "def test():", "    data = np.random.rand(6,6)", "    fig = pl.figure(1)", "    fig.clf()", "    ax = fig.add_subplot(1,1,1)", "    img = ax.imshow(data, interpolation='nearest', vmin=0.5, vmax=0.99)", "    pl.colorbar(img, ax=ax)", "", "    pl.show()"], "context_url": "https://stackoverflow.com/questions/2643953/attributeerror-while-adding-colorbar-in-matplotlib", "context_author_url": ["https://stackoverflow.com/users/1611927/michele", "https://stackoverflow.com/users/132767/gary-kerr"]}
{"error": ["Traceback (most recent call last):", "  File \"error.py\", line 25, in <module>", "    test()", "  File \"<string>\", line 5, in test", "TypeError: unsupported operand type(s) for +: 'dict' and 'dict'", ""], "code": ["def test():", "    # merge 2 dict", "    d1 = {1: [2, 3], 2: [4, 5]}", "    d2 = {3: [5], 7: [11, 2]}", "    return d1 + d2"], "context": ["", "How can I merge two Python dictionaries in a single expression?", "For dictionaries `x` and `y`, their shallowly-merged dictionary `z` takes values from `y`, replacing those from `x`.", "", "In Python 3.9.0 or greater (released 17 October 2020, PEP-584, discussed here):", "z = x | y", "", "", "In Python 3.5 or greater:", "z = {**x, **y}", "", "", "In Python 2, (or 3.4 or lower) write a function:", "def merge_two_dicts(x, y):", "    z = x.copy()   # start with keys and values of x", "    z.update(y)    # modifies z with keys and values of y", "    return z", "", "and now:", "z = merge_two_dicts(x, y)"], "ideal": ["def test():", "    # merge 2 dict", "    d1 = {1: [2, 3], 2: [4, 5]}", "    d2 = {3: [5], 7: [11, 2]}", "    return {**d1, **d2}"], "context_url": "https://stackoverflow.com/questions/38987/how-do-i-merge-two-dictionaries-in-a-single-expression-in-python", "context_author_url": ["https://stackoverflow.com/users/365102/mateen-ulhaq", "https://stackoverflow.com/users/541136/russia-must-remove-putin"]}
{"error": ["Traceback (most recent call last):", "  File \"error.py\", line 27, in <module>", "    exec(\"\\n\".join(data[\"code\"]))", "  File \"<string>\", line 11, in <module>", "TypeError: __init__() takes 1 positional argument but 2 were given", ""], "code": ["import pandas as pd", "import numpy as np", "", "def test():", "    data = {\"a\": ['1', '3', '4', '5', '6'], \"b\": ['is', 'am', 'island', 'icream', \"banana\"]}", "    df = pd.DataFrame.from_dict(data)", "    ", "    return not df['a'].str.contains(\"is\")"], "context": ["", "You can use the invert (~) operator (which acts like a not for boolean data):", "```", "new_df = df[~df[\"col\"].str.contains(word)]", "```", "", "where `new_df` is the copy returned by RHS.", "contains also accepts a regular expression...", "", "If the above throws a ValueError or TypeError, the reason is likely because you have mixed datatypes, so use `na=False`:", "```", "new_df = df[~df[\"col\"].str.contains(word, na=False)]", "```", "", "Or,", "```", "new_df = df[df[\"col\"].str.contains(word) == False]", "```", "", ""], "ideal": ["import pandas as pd", "import numpy as np", "", "def test():", "    data = {\"a\": ['1', '3', '4', '5', '6'], \"b\": ['is', 'am', 'island', 'icream', \"banana\"]}", "    df = pd.DataFrame.from_dict(data)", "    ", "    return ~df['a'].str.contains(\"is\")"], "context_url": "https://stackoverflow.com/questions/17097643/search-for-does-not-contain-on-a-dataframe-in-pandas", "context_author_url": ["https://stackoverflow.com/users/3427777/fantabolous", "https://stackoverflow.com/users/1240268/andy-hayden"]}
{"error": ["Traceback (most recent call last):", "  File \"error.py\", line 26, in <module>", "    test()", "  File \"<string>\", line 5, in test", "ValueError: The truth value of an array with more than one element is ambiguous. Use a.any() or a.all()", ""], "code": ["import numpy as np", "", "def test():", "    arr = np.array([1, 2, 3, 4, 5])", "    arr = arr[(arr > 2) and (arr <= 4)] # expect [3, 4]", "    return arr"], "context": ["", "If `a` and `b` are Boolean NumPy arrays, the `&` operation returns the elementwise-and of them:", "```", "a & b", "```", "", "That returns a Boolean array. To reduce this to a single Boolean value, use either", "```", "(a & b).any()", "```", "", "or", "```", "(a & b).all()", "```", "", "Note: if `a` and `b` are non-Boolean arrays, consider `(a - b).any()` or `(a - b).all()` instead.", "", "Rationale", "The NumPy developers felt there was no one commonly understood way to evaluate an array in Boolean context: it could mean `True` if any element is `True`, or it could mean `True` if all elements are `True`, or `True` if the array has non-zero length, just to name three possibilities.", "Since different users might have different needs and different assumptions, the", "NumPy developers refused to guess and instead decided to raise a `ValueError` whenever one tries to evaluate an array in Boolean context. Applying `and` to two numpy arrays causes the two arrays to be evaluated in Boolean context (by calling `__bool__` in Python3 or `__nonzero__` in Python2).", ""], "ideal": ["import numpy as np", "", "def test():", "    arr = np.array([1, 2, 3, 4, 5])", "    arr = arr[(arr > 2) & (arr <= 4)] # expect [3, 4]", "    return arr"], "context_url": "https://stackoverflow.com/questions/10062954/valueerror-the-truth-value-of-an-array-with-more-than-one-element-is-ambiguous", "context_author_url": ["https://stackoverflow.com/users/365102/mateen-ulhaq", "https://stackoverflow.com/users/190597/unutbu"]}
{"error": ["Traceback (most recent call last):", "  File \"error.py\", line 29, in <module>", "    test()", "  File \"<string>\", line 14, in test", "  File \"/anaconda/envs/torch13/lib/python3.8/site-packages/sklearn/linear_model/_stochastic_gradient.py\", line 851, in partial_fit", "    return self._partial_fit(", "  File \"/anaconda/envs/torch13/lib/python3.8/site-packages/sklearn/linear_model/_stochastic_gradient.py\", line 598, in _partial_fit", "    self._expanded_class_weight = compute_class_weight(", "  File \"/anaconda/envs/torch13/lib/python3.8/site-packages/sklearn/utils/class_weight.py\", line 43, in compute_class_weight", "    raise ValueError(\"classes should include all valid labels that can be in y\")", "ValueError: classes should include all valid labels that can be in y", ""], "code": ["from sklearn import linear_model", "", "def test():", "    X = [[1, 1], [2, 2.5], [2, 6.8], [4, 7]]", "    y = [1, 2, 3, 4]", "", "    sgd_clf = linear_model.SGDClassifier(loss=\"log\")", "", "    sgd_clf.fit(X, y)", "", "    X1 = [[6,9]]", "    y1=[5]", "", "    f1 = sgd_clf.partial_fit(X1,y1)", "", "    f1.predict([[6,9]])", "", "    return f1"], "context": ["", "The underlying problem seems to be that your input data to partial fit is not a subset of your original data (that was input to `.fit()`).", "That requirement is at least how I interpret the documentation for `X` and `y` in `partial_fit()`:", "> ", "> X : {array-like, sparse matrix}, shape (n_samples, n_features)> ", "> `Subset of the training data", "`> ", "> y : numpy array, shape (n_samples,)> ", "> `Subset of the target values", "`> ", "", "It also becomes apparent from the error when you use your `X1` and `y1`, with `classes = np.unique(y1)` (as suggested in the documentation, which yields:", "```", "ValueError: `classes=array([5])` is not the same as on last call to", "    partial_fit, was: array([1, 2, 3, 4])", "```", "", "Which indicates `partial_fit` is used in `fit` under the hood.", "The following example works:", "```", "X1 = X[2:3]", "y1 = y[2:3]", "", "classes = np.unique(y)", "f1 = sgd_clf.partial_fit(X1, y1, classes=classes)", "```", "", "So make sure `X1` and `y1` are included in your original data sets.", ""], "ideal": ["from sklearn import linear_model", "", "def test():", "    X = [[1, 1], [2, 2.5], [2, 6.8], [4, 7]]", "    y = [1, 2, 3, 4]", "", "    sgd_clf = linear_model.SGDClassifier(loss=\"log\")", "", "    sgd_clf.fit(X, y)", "", "    X1 = X[2:3]", "    y1 = y[2:3]", "", "    f1 = sgd_clf.partial_fit(X1,y1)", "", "    f1.predict([[6,9]])", "", "    return f1"], "context_url": "https://stackoverflow.com/questions/48902767/sgdclassifier-partial-fit-returns-error-of-classes-should-include-labels", "context_author_url": []}
{"error": ["Traceback (most recent call last):", "  File \"error.py\", line 25, in <module>", "    test()", "  File \"<string>\", line 6, in test", "  File \"/anaconda/envs/torch13/lib/python3.8/urllib/request.py\", line 222, in urlopen", "    return opener.open(url, data, timeout)", "  File \"/anaconda/envs/torch13/lib/python3.8/urllib/request.py\", line 525, in open", "    response = self._open(req, data)", "  File \"/anaconda/envs/torch13/lib/python3.8/urllib/request.py\", line 542, in _open", "    result = self._call_chain(self.handle_open, protocol, protocol +", "  File \"/anaconda/envs/torch13/lib/python3.8/urllib/request.py\", line 502, in _call_chain", "    result = func(*args)", "  File \"/anaconda/envs/torch13/lib/python3.8/urllib/request.py\", line 1383, in http_open", "    return self.do_open(http.client.HTTPConnection, req)", "  File \"/anaconda/envs/torch13/lib/python3.8/urllib/request.py\", line 1354, in do_open", "    h.request(req.get_method(), req.selector, req.data, headers,", "  File \"/anaconda/envs/torch13/lib/python3.8/http/client.py\", line 1256, in request", "    self._send_request(method, url, body, headers, encode_chunked)", "  File \"/anaconda/envs/torch13/lib/python3.8/http/client.py\", line 1267, in _send_request", "    self.putrequest(method, url, **skips)", "  File \"/anaconda/envs/torch13/lib/python3.8/http/client.py\", line 1101, in putrequest", "    self._validate_path(url)", "  File \"/anaconda/envs/torch13/lib/python3.8/http/client.py\", line 1201, in _validate_path", "    raise InvalidURL(f\"URL can't contain control characters. {url!r} \"", "http.client.InvalidURL: URL can't contain control characters. '/search?q=hello world&go=&qs=n&sk=&sc=8-13&first=10' (found at least ' ')", ""], "code": ["import urllib.request", "", "def test():", "    query = \"hello world\"", "    host = 'http://www.bing.com/search?q=%s&go=&qs=n&sk=&sc=8-13&first=10' % query", "    response = urllib.request.urlopen(host)", "    return response"], "context": ["", "The reason that \"the dog\" returns a 400 Error is because you aren't escaping the string for a URL. ", "If you do this:", "```", "import urllib, urllib2", "", "quoted_query = urllib.quote(query)", "host = 'http://www.bing.com/search?q=%s&go=&qs=n&sk=&sc=8-13&first=%s' % (quoted_query, page)", "req = urllib2.Request(host)", "req.add_header('User-Agent', User_Agent)", "response = urllib2.urlopen(req)", "```", "", "It will work.", "However I highly suggest you use requests instead of using urllib/urllib2/httplib. It's much much easier and it'll handle all of this for you.", "This is the same code with python requests:", "```", "import requests", "", "results = requests.get(\"http://www.bing.com/search\", ", "              params={'q': query, 'first': page}, ", "              headers={'User-Agent': user_agent})", "```", "", ""], "ideal": ["import urllib.request", "import urllib.parse", "", "def test():", "    query = \"hello world\"", "    quoted_query = urllib.parse.quote(query)", "    host = 'http://www.bing.com/search?q=%s&go=&qs=n&sk=&sc=8-13&first=10' % quoted_query", "    response = urllib.request.urlopen(host)", "    return response"], "context_url": "https://stackoverflow.com/questions/8840303/urllib2-http-error-400-bad-request", "context_author_url": ["https://stackoverflow.com/users/832230/asclepius", "https://stackoverflow.com/users/1142531/ravenac95"]}
{"error": ["Traceback (most recent call last):", "  File \"error.py\", line 20, in <module>", "    exec(\"\\n\".join(data[\"code\"]))", "  File \"<string>\", line 11, in <module>", "TypeError: __init__() takes 1 positional argument but 2 were given", ""], "code": ["import pickle", "from collections import defaultdict", "", "class MyDict(defaultdict):", "    code = \"100\"", "    def __init__(self):", "        super().__init__(list)", "", "c = MyDict()", "a = pickle.dumps(c)", "b = pickle.loads(a)"], "context": ["", "Types define how instances of it get pickled by defining one or more of a (fairly large) set of methods. Each has its own subtle behaviour. See the docs on the pickle protocol. In the case of `collections.defaultdict`, it uses the `__reduce__` method:", "```", ">>> l = collections.defaultdict(list)", ">>> l.__reduce__()", "(<type 'collections.defaultdict'>, (<type 'list'>,), None, None, <dictionary-itemiterator object at 0x7f031fb3c470>)", "```", "", "The first item in the tuple there is the type, and the second item is the tuple of arguments to pass to the type when instantiating it. If you don't override `__reduce__`, the first item will correctly change to your type, but the second item will not. This causes the error you see. A crude example of how you could fix it:", "```", ">>> import collections", ">>> import pickle", ">>> class C(collections.defaultdict):", "...     def __init__(self):", "...         collections.defaultdict.__init__(self, list)", "...     def __reduce__(self):", "...         t = collections.defaultdict.__reduce__(self)", "...         return (t[0], ()) + t[2:]", "...", ">>> c = C()", ">>> c[1].append(2)", ">>> c[2].append(3)", ">>> c2 = pickle.loads(pickle.dumps(c))", ">>> c2 == c", "True", "```", "", "It's only a crude example because there's more to pickling (like `__reduce_ex__`) and it's all fairly intricate. In this case, using `__getinitargs__` may be more convenient.", "Alternatively, you could make your class's `__init__` method take an optional callable, defaulting to `list`, or you could just use a function instead of a class:", "```", "def listdict():", "    return collections.defaultdict(list)", "```", "", ""], "ideal": ["import pickle", "from collections import defaultdict", "", "class MyDict(defaultdict):", "    code = \"100\"", "    def __init__(self):", "        super().__init__(list)", "", "    def __reduce__(self):", "        t = defaultdict.__reduce__(self)", "        return (t[0], ()) + t[2:]", "", "c = MyDict()", "a = pickle.dumps(c)", "b = pickle.loads(a)"], "context_url": "https://stackoverflow.com/questions/3855428/how-to-pickle-and-unpickle-instances-of-a-class-that-inherits-from-defaultdict", "context_author_url": ["https://stackoverflow.com/users/17624/thomas-wouters"]}
{"error": ["Traceback (most recent call last):", "  File \"error.py\", line 29, in <module>", "    test()", "  File \"<string>\", line 6, in test", "AttributeError: 'KMeans' object has no attribute 'labels_'", ""], "code": ["from sklearn.cluster import KMeans", "import numpy as np", "", "def test():", "    km = KMeans()", "    print(km.labels_)", "    X = np.random.rand(100, 2)", "    km.fit(X)"], "context": ["", "You have to fit your `KMeans` object first for it to have a label attribute:", "Without fitting it throws an error:", "```", "from sklearn.cluster import KMeans", "km = KMeans()", "print(km.labels_)", ">>>AttributeError: 'KMeans' object has no attribute 'labels_'", "```", "", "After fitting:", "```", "from sklearn.cluster import KMeans", "import numpy as np", "km = KMeans()", "X = np.random.rand(100, 2)", "km.fit(X)", "print(km.labels_)", ">>>[1 6 7 4 6 6 7 5 6 0 0 7 3 4 5 7 5 0 3 4 0 6 1 6 7 5 4 3 4 2 1 2 1 4 6 3 6 1 7 6 6 7 4 1 1 0 4 2 5 0 6 3 1 0 7 6 2 7 7 5 2 7 7 3 2 1 2 2 4 7 5 3 2 65 1 6 2 4 2 3 2 2 2 1 2 0 5 7 2 4 4 5 4 4 1 1 4 5 0]", "```", "", ""], "ideal": ["from sklearn.cluster import KMeans", "import numpy as np", "", "def test():", "    km = KMeans()", "    X = np.random.rand(100, 2)", "    km.fit(X)", "    print(km.labels_)"], "context_url": "https://stackoverflow.com/questions/49844928/kmeans-object-has-no-attribute-labels", "context_author_url": ["https://stackoverflow.com/users/8112138/primusa"]}
{"error": ["Traceback (most recent call last):", "  File \"error.py\", line 24, in <module>", "    test()", "  File \"<string>\", line 16, in test", "  File \"/anaconda/envs/torch13/lib/python3.8/site-packages/torch/nn/modules/module.py\", line 1130, in _call_impl", "    return forward_call(*input, **kwargs)", "  File \"/anaconda/envs/torch13/lib/python3.8/site-packages/torch/nn/modules/loss.py\", line 1164, in forward", "    return F.cross_entropy(input, target, weight=self.weight,", "  File \"/anaconda/envs/torch13/lib/python3.8/site-packages/torch/nn/functional.py\", line 3014, in cross_entropy", "    return torch._C._nn.cross_entropy_loss(input, target, weight, _Reduction.get_enum(reduction), ignore_index, label_smoothing)", "RuntimeError: expected scalar type Long but found Float", ""], "code": ["import torch", "from torch import nn", "", "def test():", "    device = torch.device(\"cuda:0\")", "    model = nn.Sequential(", "        nn.Linear(10, 12),", "        nn.ReLU(),", "        nn.Linear(12, 3)", "    )", "    loss_fn = nn.CrossEntropyLoss()", "", "    x = torch.randn(3, 10)", "    y = torch.zeros(3)", "    preds = model(x)", "    loss = loss_fn(preds, y)", "    return preds"], "context": ["", "As per the documentation and official example at pytorch webpage, The targets passed to `nn.CrossEntropyLoss()` should be in torch.long format", "```", "# official example", "import torch", "import torch.nn as nn", "loss = nn.CrossEntropyLoss()", "input = torch.randn(3, 5, requires_grad=True)", "target = torch.empty(3, dtype=torch.long).random_(5) ", "", "# if you will replace the dtype=torch.float, you will get error", "", "output = loss(input, target)", "output.backward()", "```", "", "update this line in your code as", "```", "label = torch.tensor(self.prediction.iloc[idx, :],dtype=torch.long) #updated torch.float to torch.long", "```", "", ""], "ideal": ["import torch", "from torch import nn", "", "def test():", "    device = torch.device(\"cuda:0\")", "    model = nn.Sequential(", "        nn.Linear(10, 12),", "        nn.ReLU(),", "        nn.Linear(12, 3)", "    )", "    loss_fn = nn.CrossEntropyLoss()", "", "    x = torch.randn(3, 10)", "    y = torch.zeros(3, dtype=torch.long)", "    preds = model(x)", "    loss = loss_fn(preds, y)", "    return preds"], "context_url": "https://stackoverflow.com/questions/63383347/runtimeerror-expected-object-of-scalar-type-long-but-got-scalar-type-float-for", "context_author_url": ["https://stackoverflow.com/users/13073020/mughees"]}
{"error": ["Traceback (most recent call last):", "  File \"error.py\", line 22, in <module>", "    test()", "  File \"<string>\", line 8, in test", "AttributeError: Can't pickle local object 'test.<locals>.<lambda>'", ""], "code": ["import pickle", "from collections import defaultdict", "", "def test():", "    dict1 = defaultdict(lambda: defaultdict(int))", "", "    dict1[\"class1\"] = {\"tom\": 1, \"alice\": 1}", "    str_dict1 = pickle.dumps(dict1)", "    return str_dict1"], "context": ["", "In addition to Martijn's explanation:", "A module-level function is a function which is defined at module level, that means it is not an instance method of a class, it's not nested within another function, and it is a \"real\" function with a name, not a lambda function.", "So, to pickle your `defaultdict`, create it with module-level function instead of a lambda function:", "```", "def dd():", "    return defaultdict(int)", "", "dict1 = defaultdict(dd) # dd is a module-level function", "```", "", "than you can pickle it", "```", "tmp = pickle.dumps(dict1) # no exception", "new = pickle.loads(tmp)", "```", "", ""], "ideal": ["import pickle", "from collections import defaultdict", "", "def dd():", "    return defaultdict(int)", "", "def test():", "    dict1 = defaultdict(dd)", "", "    dict1[\"class1\"] = {\"tom\": 1, \"alice\": 1}", "    str_dict1 = pickle.dumps(dict1)", "    return str_dict1"], "context_url": "https://stackoverflow.com/questions/16439301/cant-pickle-defaultdict", "context_author_url": ["https://stackoverflow.com/users/-1/community", "https://stackoverflow.com/users/142637/sloth"]}
{"error": ["Traceback (most recent call last):", "  File \"error.py\", line 25, in <module>", "    test()", "  File \"<string>\", line 5, in test", "TypeError: Tuple or struct_time argument required", ""], "code": ["import time", "", "def test():", "    timestamp = \"1284101485\"", "    return time.strftime(\"%B %d %Y\", timestamp)"], "context": ["Use datetime module:", "```", "from datetime import datetime", "ts = int('1284101485')", "", "# if you encounter a \"year is out of range\" error the timestamp", "# may be in milliseconds, try `ts /= 1000` in that case", "print(datetime.utcfromtimestamp(ts).strftime('%Y-%m-%d %H:%M:%S'))", "```"], "ideal": ["import time", "from datetime import datetime", "", "def test():", "    timestamp = 1284101485", "    return datetime.utcfromtimestamp(timestamp).strftime('%Y-%m-%d %H:%M:%S')"], "context_url": "https://stackoverflow.com/questions/3682748/converting-unix-timestamp-string-to-readable-date", "context_author_url": ["https://stackoverflow.com/users/7122272/jaroslav-bezd%c4%9bk", "https://stackoverflow.com/users/22595/micha%c5%82-niklas"]}
{"error": ["Traceback (most recent call last):", "  File \"error.py\", line 27, in <module>", "    test()", "  File \"<string>\", line 7, in test", "  File \"/anaconda/envs/torch13/lib/python3.8/site-packages/matplotlib/pyplot.py\", line 2790, in scatter", "    __ret = gca().scatter(", "  File \"/anaconda/envs/torch13/lib/python3.8/site-packages/matplotlib/__init__.py\", line 1423, in inner", "    return func(ax, *map(sanitize_sequence, args), **kwargs)", "  File \"/anaconda/envs/torch13/lib/python3.8/site-packages/matplotlib/axes/_axes.py\", line 4529, in scatter", "    raise ValueError(", "ValueError: s must be a scalar, or float array-like with the same size as x and y", ""], "code": ["from matplotlib import pyplot as plt", "", "def test():", "    XS = [\"1\", \"2\", \"3\"]", "    YS = [\"1\", \"2\", \"3\"]", "    ZS = [\"1\", \"2\", \"3\"]", "    plt.scatter(XS, YS, ZS, c='r', marker='o')"], "context": ["", "The error is because you are trying to plot three lists of `str` type objects. They need to be of `float` or similar type, and cannot be implicitly casted. You can do the type casting explicitly by making the modification below:", "```", "for column in readCSV:", "        xs = float(column[1])", "        ys = float(column[2])", "        zs = float(column[3])", "```", "", "Also note that `ax.scatter` should be outside the loop, like this", "```", "    for column in readCSV:", "        xs = float(column[1])", "        ys = float(column[2])", "        zs = float(column[3])", "", "        XS.append(xs)", "        YS.append(ys)", "        ZS.append(zs)", "", "ax.scatter(XS, YS, ZS, c='r', marker='o')", "ax.set_xlabel('X Label')", "ax.set_ylabel('Y Label')", "ax.set_zlabel('Z Label')", "```", "", "Otherwise you will end up with a new scatter plot for every row in the `.csv`. I isolated the first 5 rows of your data and plotted them with these modifications to give", "", ""], "ideal": ["from matplotlib import pyplot as plt", "", "def test():", "    XS = [1, 2, 3]", "    YS = [1, 2, 3]", "    ZS = [1, 2, 3]", "    plt.scatter(XS, YS, ZS, c='r', marker='o')"], "context_url": "https://stackoverflow.com/questions/54914981/matplotlib-error-typeerror-cannot-cast-array-data-from-dtypefloat64-to-dtyp", "context_author_url": ["https://stackoverflow.com/users/10659910/william-miller"]}
{"error": ["Traceback (most recent call last):", "  File \"error.py\", line 27, in <module>", "    test()", "  File \"<string>\", line 8, in test", "AttributeError: 'numpy.ndarray' object has no attribute 'plot'", ""], "code": ["from matplotlib import pyplot as plt", "", "", "def test():", "    fig, axes = plt.subplots(nrows=2, ncols=2)", "", "    for i in range(4):", "        axes[i].plot([1, 2, 3])", "", "    plt.show()"], "context": ["", "If you debug your program by simply printing `ax`, you'll quickly find out that `ax` is a two-dimensional array: one dimension for the rows, one for the columns.", "Thus, you need two indices to index `ax` to retrieve the actual `AxesSubplot` instance, like:", "```", "ax[1,1].plot(...)", "```", "", "If you want to iterate through the subplots in the way you do it now, by flattening `ax` first: ", "```", "ax = ax.flatten()", "```", "", "and now `ax` is a one dimensional array. I don't know if rows or columns are stepped through first, but if it's the wrong around, use the transpose:", "```", "ax = ax.T.flatten()", "```", "", "", "Of course, by now it makes more sense to simply create each subplot on the fly, because that already has an index, and the other two numbers are fixed:", "```", "for x < plots_tot:", "     ax = plt.subplot(nrows, ncols, x+1)", "```", "", "Note: you have `x <= plots_tot`, but with `x` starting at 0, you'll get an `IndexError` next with your current code (after flattening your array). Matplotlib is (unfortunately) 1-indexed for subplots. I prefer using a 0-indexed variable (Python style), and just add `+1` for the subplot index (like above).", ""], "ideal": ["from matplotlib import pyplot as plt", "", "", "def test():", "    fig, axes = plt.subplots(nrows=2, ncols=2)", "", "    for row in range(2):", "        for col in range(2):", "            axes[row, col].plot([1, 2, 3])", "", "    plt.show()"], "context_url": "https://stackoverflow.com/questions/37967786/axes-from-plt-subplots-is-a-numpy-ndarray-object-and-has-no-attribute-plot", "context_author_url": []}
{"error": ["Traceback (most recent call last):", "  File \"error.py\", line 26, in <module>", "    test()", "  File \"<string>\", line 4, in test", "  File \"<__array_function__ internals>\", line 180, in bincount", "ValueError: object of too small depth for desired array", ""], "code": ["import numpy as np", "", "def test():", "    np.bincount(0)"], "context": ["", "According to the traceback the error is raised by `bincount`.  This reproduces it:", "```", "In [13]: np.bincount(0)                                                                          ", "---------------------------------------------------------------------------", "ValueError                                Traceback (most recent call last)", "<ipython-input-13-65825aeaf27a> in <module>", "----> 1 np.bincount(0)", "", "<__array_function__ internals> in bincount(*args, **kwargs)", "", "ValueError: object of too small depth for desired array", "In [14]: np.bincount(np.arange(5))                                                               ", "Out[14]: array([1, 1, 1, 1, 1])", "```", "", "`bincount` works with a 1d array; it raises this error if given a scalar.", "Now work you way back through to `traceback` to figure out what variable in your code is a scalar when it should be an array.", ""], "ideal": ["import numpy as np", "", "def test():", "    np.bincount(np.array([0]))"], "context_url": "https://stackoverflow.com/questions/59770191/valueerror-object-of-too-small-depth-for-desired-array?rq=1", "context_author_url": ["https://stackoverflow.com/users/901925/hpaulj"]}
{"error": ["Traceback (most recent call last):", "  File \"error.py\", line 20, in <module>", "    exec(\"\\n\".join(data[\"code\"]))", "  File \"<string>\", line 10, in <module>", "TypeError: __init__() takes 1 positional argument but 2 were given", ""], "code": ["import pickle", "", "class MyError(Exception):", "    code = \"100\"", "    def __init__(self):", "        super().__init__(\"Exception in My Class\")", "", "c = MyError()    ", "a = pickle.dumps(c)", "b = pickle.loads(a)     "], "context": ["", "`BaseException` implements a __reduce__ method that returns a tuple with the type and the value of `self.args` (a third value is included if there are more attributes besides `.args`):", "```", ">>> Error().__reduce__()", "(<class '__main__.Error'>, ('Some error message',))", "```", "", "This tuple is pickled and when unpickling, used to re-create the instance. The class also implements __setstate__, which would be called if there was a third element in the `__reduce__` return tuple, but that's not relevant here.", "You'd have to provide a different implementation of `__reduce__`:", "```", "class Error(Exception):", "    def __init__(self):", "        super().__init__(\"Some error message\")", "    def __reduce__(self):", "        return type(self), ()", "```", "", ""], "ideal": ["import pickle", "", "class MyError(Exception):", "    code = \"100\"", "    def __init__(self):", "        super().__init__(\"Exception in My Class\")", "    def __reduce__(self):", "        return type(self), ()", "", "c = MyError()    ", "a = pickle.dumps(c)", "b = pickle.loads(a)     "], "context_url": "https://stackoverflow.com/questions/49715881/how-to-pickle-inherited-exceptions", "context_author_url": ["https://stackoverflow.com/users/100297/martijn-pieters"]}
{"error": ["Traceback (most recent call last):", "  File \"error.py\", line 29, in <module>", "    test()", "  File \"<string>\", line 8, in test", "  File \"/anaconda/envs/torch13/lib/python3.8/site-packages/pandas/core/frame.py\", line 3978, in __setitem__", "    self._set_item(key, value)", "  File \"/anaconda/envs/torch13/lib/python3.8/site-packages/pandas/core/frame.py\", line 4172, in _set_item", "    value = self._sanitize_column(value)", "  File \"/anaconda/envs/torch13/lib/python3.8/site-packages/pandas/core/frame.py\", line 4912, in _sanitize_column", "    com.require_length_match(value, self.index)", "  File \"/anaconda/envs/torch13/lib/python3.8/site-packages/pandas/core/common.py\", line 561, in require_length_match", "    raise ValueError(", "ValueError: Length of values (2) does not match length of index (3)", ""], "code": ["import pandas as pd", "", "def test():", "    data = {\"a\": [\"hello\", \"hello\", \"hi chatgpt\"], \"b\": [3, 1, 3]}", "    df = pd.DataFrame.from_dict(data)", "", "    for col in df:", "        df[col]=df[col].unique()", "    return df"], "context": ["", "The error comes up when you are trying to assign a list of numpy array of different length to a data frame, and it can be reproduced as follows:", "A data frame of four rows:", "```", "df = pd.DataFrame({'A': [1,2,3,4]})", "```", "", "Now trying to assign a list/array of two elements to it:", "```", "df['B'] = [3,4]   # or df['B'] = np.array([3,4])", "```", "", "Both errors out:", "> ", "> ValueError: Length of values does not match length of index> ", "", "Because the data frame has four rows but the list and array has only two elements.", "Work around Solution (use with caution): convert the list/array to a pandas Series, and then when you do assignment, missing index in the Series will be filled with NaN:", "```", "df['B'] = pd.Series([3,4])", "", "df", "#   A     B", "#0  1   3.0", "#1  2   4.0", "#2  3   NaN          # NaN because the value at index 2 and 3 doesn't exist in the Series", "#3  4   NaN", "```", "", "", "For your specific problem, if you don't care about the index or the correspondence of values between columns, you can reset index for each column after dropping the duplicates:", "```", "df.apply(lambda col: col.drop_duplicates().reset_index(drop=True))", "", "#   A     B", "#0  1   1.0", "#1  2   5.0", "#2  7   9.0", "#3  8   NaN", "```", "", ""], "ideal": ["import pandas as pd", "", "def test():", "    data = {\"a\": [\"hello\", \"hello\", \"hi chatgpt\"], \"b\": [3, 1, 3]}", "    df = pd.DataFrame.from_dict(data)", "", "    for col in df:", "        df[col]=pd.Series(df[col].unique())", "    return df"], "context_url": "https://stackoverflow.com/questions/42382263/valueerror-length-of-values-does-not-match-length-of-index-pandas-dataframe-u", "context_author_url": ["https://stackoverflow.com/users/4983450/psidom"]}
{"error": ["Traceback (most recent call last):", "  File \"error.py\", line 22, in <module>", "    test()", "  File \"<string>\", line 5, in test", "  File \"/anaconda/envs/torch13/lib/python3.8/json/__init__.py\", line 231, in dumps", "    return _default_encoder.encode(obj)", "  File \"/anaconda/envs/torch13/lib/python3.8/json/encoder.py\", line 199, in encode", "    chunks = self.iterencode(o, _one_shot=True)", "  File \"/anaconda/envs/torch13/lib/python3.8/json/encoder.py\", line 257, in iterencode", "    return _iterencode(o, 0)", "  File \"/anaconda/envs/torch13/lib/python3.8/json/encoder.py\", line 179, in default", "    raise TypeError(f'Object of type {o.__class__.__name__} '", "TypeError: Object of type set is not JSON serializable", ""], "code": ["import json", "", "def test():", "    a = {1, 2, 3, 4}", "    json_a = json.dumps(a)", "    return json_a"], "context": ["", "`{1, 3}` is a set, which as the error points out, cannot be serialized to JSON - the only collection types in JSON are lists (called arrays in JSON) and dictionaries (called objects in JSON).", "You'll need to convert it to a list:", "```", "converted = list(my_data)", "save_json(my_filename, converted)", "```", "", ""], "ideal": ["import json", "", "def test():", "    a = {1, 2, 3, 4}", "    json_a = json.dumps(list(a))", "    return json_a"], "context_url": "https://stackoverflow.com/questions/42295935/typeerror-1-3-is-not-json-serializab", "context_author_url": ["https://stackoverflow.com/users/1014938/zero-piraeus"]}
{"error": ["Traceback (most recent call last):", "  File \"error.py\", line 30, in <module>", "    test()", "  File \"<string>\", line 8, in test", "AssertionError: BLEU score is expected to be 0.654695908848467, but get 0.537284965911771", ""], "code": ["from nltk.translate.bleu_score import sentence_bleu", "", "def test():", "    reference = [['this', 'is', 'a', 'simple', 'test']]", "    candidate = ['this', 'is', 'a', 'simple', 'function', 'test']", "    score = sentence_bleu(reference, candidate)", "", "    assert score == 0.654695908848467, f\"BLEU score is expected to be 0.654695908848467, but get {score}\""], "context": ["", "By default, `sentence_bleu` is configured with 4 weights: 0.25 for unigram, 0.25 for bigram, 0.25 for trigram, 0.25 for quadrigram. The length of `weights` give the order of ngram, so the BLEU score is computed for 4 levels of ngrams.", "When you use `weights=[1]`, you only analyze unigram:", "```", "reference = [['this', 'is', 'ae', 'test','rest','pep','did']]", "candidate = ['this', 'is', 'ad', 'test','rest','pep','did']", "", ">>> sentence_bleu(reference, candidate)  # default weights, order of ngrams=4", "0.488923022434901", "```", "", "But you can also consider unigrams are more important than bigrams which are more important than tri and quadigrams:", "```", ">>> sentence_bleu(reference, candidate, weights=[0.5, 0.3, 0.1, 0.1])", "0.6511772622175621", "```", "", "You can also use SmoothingFunction methods and read the docstring from source code to better understanding.", ""], "ideal": ["from nltk.translate.bleu_score import sentence_bleu", "", "def test():", "    reference = [['this', 'is', 'a', 'simple', 'test']]", "    candidate = ['this', 'is', 'a', 'simple', 'function', 'test']", "    score = sentence_bleu(reference, candidate, weights=[0.5, 0.3, 0.1, 0.1])", "", "    assert score == 0.654695908848467, f\"BLEU score is expected to be 0.654695908848467, but get {score}\""], "context_url": "https://stackoverflow.com/questions/75624727/why-i-am-getting-less-bleu-score", "context_author_url": ["https://stackoverflow.com/users/15239951/corralien"]}
{"error": ["Traceback (most recent call last):", "  File \"error.py\", line 29, in <module>", "    test()", "  File \"<string>\", line 11, in test", "TypeError: fit() missing 1 required positional argument: 'y'", ""], "code": ["import sklearn", "import numpy as np", "import sklearn.ensemble as ensemble", "", "def test():", "    X = np.random.randn(32, 100)", "    y = np.random.randint(0, 2, (32, 100))", "    x_train, x_test, y_train, y_test = sklearn.model_selection.train_test_split(X, y, test_size=0.2)", "", "    etr = ensemble.ExtraTreesRegressor", "    etr.fit(x_train, y_train)", "    acc = etr.score(x_test, y_test)"], "context": ["", "The problem is here", "```", "etr = ensemble.ExtraTreesRegressor", "etr.fit(x_train, y_train)", "```", "", "You need to instantiate `ensemble.ExtraTreesRegressor` before calling `fit` on it. Change this code to", "```", "etr = ensemble.ExtraTreesRegressor()", "etr.fit(x_train, y_train)", "```", "", "You get the seemingly strange error that `y` is missing because `.fit` is an instance method, so the first argument to this function is actually `self`. When you call `.fit` on an instance, `self` is passed automatically. If you call `.fit` on the class (as opposed to the instance), you would have to supply `self`. So your code is equivalent to `ensemble.ExtraTreesRegressor.fit(self=x_train, x=y_train)`.", "For an example of the difference, please see the example below. The two forms are functionally equivalent, but you can see that the first form is clunky.", "```", "from sklearn import ensemble", "", "# Synthetic data.", "x = [[0]]", "y = [1]", "", "myinstance = ensemble.ExtraTreesRegressor()", "ensemble.ExtraTreesRegressor.fit(myinstance, x, y)", "", "etr = ensemble.ExtraTreesRegressor()", "etr.fit(x, y)", "```", "", ""], "ideal": ["import sklearn", "import numpy as np", "import sklearn.ensemble as ensemble", "", "def test():", "    X = np.random.randn(32, 100)", "    y = np.random.randint(0, 2, (32, 100))", "    x_train, x_test, y_train, y_test = sklearn.model_selection.train_test_split(X, y, test_size=0.2)", "", "    etr = ensemble.ExtraTreesRegressor()", "    etr.fit(x_train, y_train)", "    acc = etr.score(x_test, y_test)"], "context_url": "https://stackoverflow.com/questions/63223374/typeerror-fit-missing-1-required-positional-argument-y-using-sklearn-ex", "context_author_url": ["https://stackoverflow.com/users/5666087/jkr"]}
{"error": ["Traceback (most recent call last):", "  File \"error.py\", line 27, in <module>", "    test()", "  File \"<string>\", line 5, in test", "  File \"/anaconda/envs/torch13/lib/python3.8/site-packages/matplotlib/pyplot.py\", line 2790, in scatter", "    __ret = gca().scatter(", "  File \"/anaconda/envs/torch13/lib/python3.8/site-packages/matplotlib/__init__.py\", line 1423, in inner", "    return func(ax, *map(sanitize_sequence, args), **kwargs)", "  File \"/anaconda/envs/torch13/lib/python3.8/site-packages/matplotlib/axes/_axes.py\", line 4634, in scatter", "    collection._internal_update(kwargs)", "  File \"/anaconda/envs/torch13/lib/python3.8/site-packages/matplotlib/artist.py\", line 1186, in _internal_update", "    return self._update_props(", "  File \"/anaconda/envs/torch13/lib/python3.8/site-packages/matplotlib/artist.py\", line 1160, in _update_props", "    raise AttributeError(", "AttributeError: PathCollection.set() got an unexpected keyword argument 'title'", ""], "code": ["import matplotlib.pyplot as plt", "", "def test():", "    x= [8,3,5]; y = [3,4,5]", "    plt.scatter(x,y, title=\"title\")", "    plt.show()"], "context": ["", "From the documentation of plt.scatter() there is no such arguments to set the title or labels. ", "But neither does the plt.plot() command have such arguments. `plt.plot(x,y, title=\"title\")` throws an error `AttributeError: Unknown property title`. So I wonder why this should work in either case.", "In any case, the usual way to set the title is `plt.title`. The usual way to set the labels is `plt.xlabel`and `plt.ylabel`.", "```", "import matplotlib.pyplot as plt", "", "x= [8,3,5]; y = [3,4,5]", "plt.scatter(x,y)", "plt.title(\"title\")", "plt.xlabel(\"x-label\")", "plt.ylabel(\"y-label\")", "plt.show()", "```", "", ""], "ideal": ["import matplotlib.pyplot as plt", "", "def test():", "    x= [8,3,5]; y = [3,4,5]", "    plt.scatter(x, y)", "    plt.title(\"title\")", "    plt.show()"], "context_url": "https://stackoverflow.com/questions/42223587/how-to-add-title-and-xlabel-and-ylabel", "context_author_url": ["https://stackoverflow.com/users/4124317/importanceofbeingernest"]}
{"error": ["Traceback (most recent call last):", "  File \"error.py\", line 25, in <module>", "    test()", "  File \"<string>\", line 7, in test", "ValueError: math domain error", ""], "code": ["import numpy as np", "import math", "def test():", "    a = (np.arange(10) - 1).tolist()", "    rslt = []", "    for i in a:", "        rslt.append(math.log(i))", "", "    return rslt"], "context": ["", "Your code is doing a `log` of a number that is less than or equal to zero. That's mathematically undefined, so Python's `log` function raises an exception. Here's an example:", "```", ">>> from math import log", ">>> log(-1)", "Traceback (most recent call last):", "  File \"<pyshell#59>\", line 1, in <module>", "    log(-1)", "ValueError: math domain error", "```", "", "Without knowing what your `newtonRaphson2` function does, I'm not sure I can guess where the invalid `x[2]` value is coming from, but hopefully this will lead you on the right track.", ""], "ideal": ["import numpy as np", "import math", "def test():", "    a = np.arange(10) - 1", "    rslt = np.log(a)", "    return rslt"], "context_url": "https://stackoverflow.com/questions/15890503/why-does-math-log-result-in-valueerror-math-domain-error", "context_author_url": ["https://stackoverflow.com/users/1405065/blckknght"]}
{"error": ["Traceback (most recent call last):", "  File \"error.py\", line 27, in <module>", "    test()", "  File \"<string>\", line 7, in test", "  File \"/anaconda/envs/torch13/lib/python3.8/site-packages/matplotlib/_api/__init__.py\", line 224, in __getattr__", "    raise AttributeError(", "AttributeError: module 'matplotlib' has no attribute 'xlabel'", ""], "code": ["import seaborn as sns", "import matplotlib as plt", "", "def test():", "    df = sns.load_dataset(\"penguins\")", "    sns.barplot(data=df, x=\"island\", y=\"body_mass_g\")", "    plt.xlabel(\"Island\", size=15)", "    plt.ylabel(\"Body Message\", size=15)", "    plt.title(\"Penguins\", size=18)", "    plt.show()"], "context": ["", "Your `import` statement is wrong. Those methods belong to `pyplot`. I.e., you should have imported it like this:", "```", "import matplotlib.pyplot as plt", "```", "", ""], "ideal": ["import seaborn as sns", "import matplotlib.pyplot as plt", "", "def test():", "    df = sns.load_dataset(\"penguins\")", "    sns.barplot(data=df, x=\"island\", y=\"body_mass_g\")", "    plt.xlabel(\"Island\", size=15)", "    plt.ylabel(\"Body Message\", size=15)", "    plt.title(\"Penguins\", size=18)", "    plt.show()"], "context_url": "https://stackoverflow.com/questions/63677950/attributeerror-module-matplotlib-has-no-attribute-xlabel", "context_author_url": ["https://stackoverflow.com/users/2422776/mureinik"]}
{"error": ["Traceback (most recent call last):", "  File \"error.py\", line 29, in <module>", "    test()", "  File \"<string>\", line 7, in test", "AttributeError: 'LabelEncoder' object has no attribute 'classes_'", ""], "code": ["from sklearn.preprocessing import LabelEncoder", "import numpy as np", "", "def test():", "    y = np.random.randint(0, 10, (32,))", "    encoder =  LabelEncoder()", "    print(encoder.classes_)", "    return encoder.fit_transform(y)"], "context": ["", "You need to call `fit(...)` or `fit_transform(...)` on your `LabelEncoder` before you try an access `classes_`, or you will get this error.  The attribute is created by fitting.", ""], "ideal": ["from sklearn.preprocessing import LabelEncoder", "import numpy as np", "", "def test():", "    y = np.random.randint(0, 10, (32,))", "    encoder =  LabelEncoder()", "    return encoder.fit_transform(y)", "    print(encoder.classes_)"], "context_url": "https://stackoverflow.com/questions/54600156/scikit-learns-attributeerror-labelencoder-object-has-no-attribute-classes", "context_author_url": ["https://stackoverflow.com/users/452210/javabrett"]}
